{
  "name": "tile-building",
  "description": "Modular building block, 16x16x16 with window patterns",
  "gridSize": [
    16,
    16,
    16
  ],
  "origin": "center-bottom",
  "repeatable": false,
  "voxels": [
    {
      "x": 0,
      "y": 0,
      "z": 0,
      "color": "#6a6a6a"
    },
    {
      "x": 0,
      "y": 0,
      "z": 1,
      "color": "#9a9a9a"
    },
    {
      "x": 0,
      "y": 0,
      "z": 2,
      "color": "#8a8a8a"
    },
    {
      "x": 0,
      "y": 0,
      "z": 3,
      "color": "#8a8a8a"
    },
    {
      "x": 0,
      "y": 0,
      "z": 4,
      "color": "#8a8a8a"
    },
    {
      "x": 0,
      "y": 0,
      "z": 5,
      "color": "#6a6a6a"
    },
    {
      "x": 0,
      "y": 0,
      "z": 6,
      "color": "#9a9a9a"
    },
    {
      "x": 0,
      "y": 0,
      "z": 7,
      "color": "#8a8a8a"
    },
    {
      "x": 0,
      "y": 0,
      "z": 8,
      "color": "#8a8a8a"
    },
    {
      "x": 0,
      "y": 0,
      "z": 9,
      "color": "#8a8a8a"
    },
    {
      "x": 0,
      "y": 0,
      "z": 10,
      "color": "#6a6a6a"
    },
    {
      "x": 0,
      "y": 0,
      "z": 11,
      "color": "#9a9a9a"
    },
    {
      "x": 0,
      "y": 0,
      "z": 12,
      "color": "#8a8a8a"
    },
    {
      "x": 0,
      "y": 0,
      "z": 13,
      "color": "#8a8a8a"
    },
    {
      "x": 0,
      "y": 0,
      "z": 14,
      "color": "#8a8a8a"
    },
    {
      "x": 0,
      "y": 0,
      "z": 15,
      "color": "#6a6a6a"
    },
    {
      "x": 0,
      "y": 1,
      "z": 0,
      "color": "#9a9a9a"
    },
    {
      "x": 0,
      "y": 1,
      "z": 1,
      "color": "#8a8a8a"
    },
    {
      "x": 0,
      "y": 1,
      "z": 2,
      "color": "#8a8a8a"
    },
    {
      "x": 0,
      "y": 1,
      "z": 3,
      "color": "#8a8a8a"
    },
    {
      "x": 0,
      "y": 1,
      "z": 4,
      "color": "#6a6a6a"
    },
    {
      "x": 0,
      "y": 1,
      "z": 5,
      "color": "#9a9a9a"
    },
    {
      "x": 0,
      "y": 1,
      "z": 6,
      "color": "#8a8a8a"
    },
    {
      "x": 0,
      "y": 1,
      "z": 7,
      "color": "#8a8a8a"
    },
    {
      "x": 0,
      "y": 1,
      "z": 8,
      "color": "#8a8a8a"
    },
    {
      "x": 0,
      "y": 1,
      "z": 9,
      "color": "#6a6a6a"
    },
    {
      "x": 0,
      "y": 1,
      "z": 10,
      "color": "#9a9a9a"
    },
    {
      "x": 0,
      "y": 1,
      "z": 11,
      "color": "#8a8a8a"
    },
    {
      "x": 0,
      "y": 1,
      "z": 12,
      "color": "#8a8a8a"
    },
    {
      "x": 0,
      "y": 1,
      "z": 13,
      "color": "#8a8a8a"
    },
    {
      "x": 0,
      "y": 1,
      "z": 14,
      "color": "#6a6a6a"
    },
    {
      "x": 0,
      "y": 1,
      "z": 15,
      "color": "#9a9a9a"
    },
    {
      "x": 0,
      "y": 2,
      "z": 0,
      "color": "#8a8a8a"
    },
    {
      "x": 0,
      "y": 2,
      "z": 1,
      "color": "#8a8a8a"
    },
    {
      "x": 0,
      "y": 2,
      "z": 2,
      "color": "#8a8a8a"
    },
    {
      "x": 0,
      "y": 2,
      "z": 3,
      "color": "#6a6a6a"
    },
    {
      "x": 0,
      "y": 2,
      "z": 4,
      "color": "#9a9a9a"
    },
    {
      "x": 0,
      "y": 2,
      "z": 5,
      "color": "#8a8a8a"
    },
    {
      "x": 0,
      "y": 2,
      "z": 6,
      "color": "#8a8a8a"
    },
    {
      "x": 0,
      "y": 2,
      "z": 7,
      "color": "#8a8a8a"
    },
    {
      "x": 0,
      "y": 2,
      "z": 8,
      "color": "#6a6a6a"
    },
    {
      "x": 0,
      "y": 2,
      "z": 9,
      "color": "#9a9a9a"
    },
    {
      "x": 0,
      "y": 2,
      "z": 10,
      "color": "#8a8a8a"
    },
    {
      "x": 0,
      "y": 2,
      "z": 11,
      "color": "#8a8a8a"
    },
    {
      "x": 0,
      "y": 2,
      "z": 12,
      "color": "#8a8a8a"
    },
    {
      "x": 0,
      "y": 2,
      "z": 13,
      "color": "#6a6a6a"
    },
    {
      "x": 0,
      "y": 2,
      "z": 14,
      "color": "#9a9a9a"
    },
    {
      "x": 0,
      "y": 2,
      "z": 15,
      "color": "#8a8a8a"
    },
    {
      "x": 0,
      "y": 3,
      "z": 0,
      "color": "#8a8a8a"
    },
    {
      "x": 0,
      "y": 3,
      "z": 1,
      "color": "#8a8a8a"
    },
    {
      "x": 0,
      "y": 3,
      "z": 2,
      "color": "#4a6a8a"
    },
    {
      "x": 0,
      "y": 3,
      "z": 3,
      "color": "#4a6a8a"
    },
    {
      "x": 0,
      "y": 3,
      "z": 4,
      "color": "#8a8a8a"
    },
    {
      "x": 0,
      "y": 3,
      "z": 5,
      "color": "#8a8a8a"
    },
    {
      "x": 0,
      "y": 3,
      "z": 6,
      "color": "#8a8a8a"
    },
    {
      "x": 0,
      "y": 3,
      "z": 7,
      "color": "#6a6a6a"
    },
    {
      "x": 0,
      "y": 3,
      "z": 8,
      "color": "#9a9a9a"
    },
    {
      "x": 0,
      "y": 3,
      "z": 9,
      "color": "#8a8a8a"
    },
    {
      "x": 0,
      "y": 3,
      "z": 10,
      "color": "#4a6a8a"
    },
    {
      "x": 0,
      "y": 3,
      "z": 11,
      "color": "#4a6a8a"
    },
    {
      "x": 0,
      "y": 3,
      "z": 12,
      "color": "#6a6a6a"
    },
    {
      "x": 0,
      "y": 3,
      "z": 13,
      "color": "#9a9a9a"
    },
    {
      "x": 0,
      "y": 3,
      "z": 14,
      "color": "#8a8a8a"
    },
    {
      "x": 0,
      "y": 3,
      "z": 15,
      "color": "#8a8a8a"
    },
    {
      "x": 0,
      "y": 4,
      "z": 0,
      "color": "#8a8a8a"
    },
    {
      "x": 0,
      "y": 4,
      "z": 1,
      "color": "#6a6a6a"
    },
    {
      "x": 0,
      "y": 4,
      "z": 2,
      "color": "#4a6a8a"
    },
    {
      "x": 0,
      "y": 4,
      "z": 3,
      "color": "#4a6a8a"
    },
    {
      "x": 0,
      "y": 4,
      "z": 4,
      "color": "#8a8a8a"
    },
    {
      "x": 0,
      "y": 4,
      "z": 5,
      "color": "#8a8a8a"
    },
    {
      "x": 0,
      "y": 4,
      "z": 6,
      "color": "#6a6a6a"
    },
    {
      "x": 0,
      "y": 4,
      "z": 7,
      "color": "#9a9a9a"
    },
    {
      "x": 0,
      "y": 4,
      "z": 8,
      "color": "#8a8a8a"
    },
    {
      "x": 0,
      "y": 4,
      "z": 9,
      "color": "#8a8a8a"
    },
    {
      "x": 0,
      "y": 4,
      "z": 10,
      "color": "#4a6a8a"
    },
    {
      "x": 0,
      "y": 4,
      "z": 11,
      "color": "#4a6a8a"
    },
    {
      "x": 0,
      "y": 4,
      "z": 12,
      "color": "#9a9a9a"
    },
    {
      "x": 0,
      "y": 4,
      "z": 13,
      "color": "#8a8a8a"
    },
    {
      "x": 0,
      "y": 4,
      "z": 14,
      "color": "#8a8a8a"
    },
    {
      "x": 0,
      "y": 4,
      "z": 15,
      "color": "#8a8a8a"
    },
    {
      "x": 0,
      "y": 5,
      "z": 0,
      "color": "#6a6a6a"
    },
    {
      "x": 0,
      "y": 5,
      "z": 1,
      "color": "#9a9a9a"
    },
    {
      "x": 0,
      "y": 5,
      "z": 2,
      "color": "#8a8a8a"
    },
    {
      "x": 0,
      "y": 5,
      "z": 3,
      "color": "#8a8a8a"
    },
    {
      "x": 0,
      "y": 5,
      "z": 4,
      "color": "#8a8a8a"
    },
    {
      "x": 0,
      "y": 5,
      "z": 5,
      "color": "#6a6a6a"
    },
    {
      "x": 0,
      "y": 5,
      "z": 6,
      "color": "#9a9a9a"
    },
    {
      "x": 0,
      "y": 5,
      "z": 7,
      "color": "#8a8a8a"
    },
    {
      "x": 0,
      "y": 5,
      "z": 8,
      "color": "#8a8a8a"
    },
    {
      "x": 0,
      "y": 5,
      "z": 9,
      "color": "#8a8a8a"
    },
    {
      "x": 0,
      "y": 5,
      "z": 10,
      "color": "#6a6a6a"
    },
    {
      "x": 0,
      "y": 5,
      "z": 11,
      "color": "#9a9a9a"
    },
    {
      "x": 0,
      "y": 5,
      "z": 12,
      "color": "#8a8a8a"
    },
    {
      "x": 0,
      "y": 5,
      "z": 13,
      "color": "#8a8a8a"
    },
    {
      "x": 0,
      "y": 5,
      "z": 14,
      "color": "#8a8a8a"
    },
    {
      "x": 0,
      "y": 5,
      "z": 15,
      "color": "#6a6a6a"
    },
    {
      "x": 0,
      "y": 6,
      "z": 0,
      "color": "#9a9a9a"
    },
    {
      "x": 0,
      "y": 6,
      "z": 1,
      "color": "#8a8a8a"
    },
    {
      "x": 0,
      "y": 6,
      "z": 2,
      "color": "#8a8a8a"
    },
    {
      "x": 0,
      "y": 6,
      "z": 3,
      "color": "#8a8a8a"
    },
    {
      "x": 0,
      "y": 6,
      "z": 4,
      "color": "#6a6a6a"
    },
    {
      "x": 0,
      "y": 6,
      "z": 5,
      "color": "#9a9a9a"
    },
    {
      "x": 0,
      "y": 6,
      "z": 6,
      "color": "#8a8a8a"
    },
    {
      "x": 0,
      "y": 6,
      "z": 7,
      "color": "#8a8a8a"
    },
    {
      "x": 0,
      "y": 6,
      "z": 8,
      "color": "#8a8a8a"
    },
    {
      "x": 0,
      "y": 6,
      "z": 9,
      "color": "#6a6a6a"
    },
    {
      "x": 0,
      "y": 6,
      "z": 10,
      "color": "#9a9a9a"
    },
    {
      "x": 0,
      "y": 6,
      "z": 11,
      "color": "#8a8a8a"
    },
    {
      "x": 0,
      "y": 6,
      "z": 12,
      "color": "#8a8a8a"
    },
    {
      "x": 0,
      "y": 6,
      "z": 13,
      "color": "#8a8a8a"
    },
    {
      "x": 0,
      "y": 6,
      "z": 14,
      "color": "#6a6a6a"
    },
    {
      "x": 0,
      "y": 6,
      "z": 15,
      "color": "#9a9a9a"
    },
    {
      "x": 0,
      "y": 7,
      "z": 0,
      "color": "#8a8a8a"
    },
    {
      "x": 0,
      "y": 7,
      "z": 1,
      "color": "#8a8a8a"
    },
    {
      "x": 0,
      "y": 7,
      "z": 2,
      "color": "#8a8a8a"
    },
    {
      "x": 0,
      "y": 7,
      "z": 3,
      "color": "#6a6a6a"
    },
    {
      "x": 0,
      "y": 7,
      "z": 4,
      "color": "#9a9a9a"
    },
    {
      "x": 0,
      "y": 7,
      "z": 5,
      "color": "#8a8a8a"
    },
    {
      "x": 0,
      "y": 7,
      "z": 6,
      "color": "#8a8a8a"
    },
    {
      "x": 0,
      "y": 7,
      "z": 7,
      "color": "#8a8a8a"
    },
    {
      "x": 0,
      "y": 7,
      "z": 8,
      "color": "#6a6a6a"
    },
    {
      "x": 0,
      "y": 7,
      "z": 9,
      "color": "#9a9a9a"
    },
    {
      "x": 0,
      "y": 7,
      "z": 10,
      "color": "#8a8a8a"
    },
    {
      "x": 0,
      "y": 7,
      "z": 11,
      "color": "#8a8a8a"
    },
    {
      "x": 0,
      "y": 7,
      "z": 12,
      "color": "#8a8a8a"
    },
    {
      "x": 0,
      "y": 7,
      "z": 13,
      "color": "#6a6a6a"
    },
    {
      "x": 0,
      "y": 7,
      "z": 14,
      "color": "#9a9a9a"
    },
    {
      "x": 0,
      "y": 7,
      "z": 15,
      "color": "#8a8a8a"
    },
    {
      "x": 0,
      "y": 8,
      "z": 0,
      "color": "#8a8a8a"
    },
    {
      "x": 0,
      "y": 8,
      "z": 1,
      "color": "#8a8a8a"
    },
    {
      "x": 0,
      "y": 8,
      "z": 2,
      "color": "#6a6a6a"
    },
    {
      "x": 0,
      "y": 8,
      "z": 3,
      "color": "#9a9a9a"
    },
    {
      "x": 0,
      "y": 8,
      "z": 4,
      "color": "#8a8a8a"
    },
    {
      "x": 0,
      "y": 8,
      "z": 5,
      "color": "#8a8a8a"
    },
    {
      "x": 0,
      "y": 8,
      "z": 6,
      "color": "#8a8a8a"
    },
    {
      "x": 0,
      "y": 8,
      "z": 7,
      "color": "#6a6a6a"
    },
    {
      "x": 0,
      "y": 8,
      "z": 8,
      "color": "#9a9a9a"
    },
    {
      "x": 0,
      "y": 8,
      "z": 9,
      "color": "#8a8a8a"
    },
    {
      "x": 0,
      "y": 8,
      "z": 10,
      "color": "#8a8a8a"
    },
    {
      "x": 0,
      "y": 8,
      "z": 11,
      "color": "#8a8a8a"
    },
    {
      "x": 0,
      "y": 8,
      "z": 12,
      "color": "#6a6a6a"
    },
    {
      "x": 0,
      "y": 8,
      "z": 13,
      "color": "#9a9a9a"
    },
    {
      "x": 0,
      "y": 8,
      "z": 14,
      "color": "#8a8a8a"
    },
    {
      "x": 0,
      "y": 8,
      "z": 15,
      "color": "#8a8a8a"
    },
    {
      "x": 0,
      "y": 9,
      "z": 0,
      "color": "#8a8a8a"
    },
    {
      "x": 0,
      "y": 9,
      "z": 1,
      "color": "#6a6a6a"
    },
    {
      "x": 0,
      "y": 9,
      "z": 2,
      "color": "#4a6a8a"
    },
    {
      "x": 0,
      "y": 9,
      "z": 3,
      "color": "#4a6a8a"
    },
    {
      "x": 0,
      "y": 9,
      "z": 4,
      "color": "#8a8a8a"
    },
    {
      "x": 0,
      "y": 9,
      "z": 5,
      "color": "#8a8a8a"
    },
    {
      "x": 0,
      "y": 9,
      "z": 6,
      "color": "#6a6a6a"
    },
    {
      "x": 0,
      "y": 9,
      "z": 7,
      "color": "#9a9a9a"
    },
    {
      "x": 0,
      "y": 9,
      "z": 8,
      "color": "#8a8a8a"
    },
    {
      "x": 0,
      "y": 9,
      "z": 9,
      "color": "#8a8a8a"
    },
    {
      "x": 0,
      "y": 9,
      "z": 10,
      "color": "#4a6a8a"
    },
    {
      "x": 0,
      "y": 9,
      "z": 11,
      "color": "#4a6a8a"
    },
    {
      "x": 0,
      "y": 9,
      "z": 12,
      "color": "#9a9a9a"
    },
    {
      "x": 0,
      "y": 9,
      "z": 13,
      "color": "#8a8a8a"
    },
    {
      "x": 0,
      "y": 9,
      "z": 14,
      "color": "#8a8a8a"
    },
    {
      "x": 0,
      "y": 9,
      "z": 15,
      "color": "#8a8a8a"
    },
    {
      "x": 0,
      "y": 10,
      "z": 0,
      "color": "#6a6a6a"
    },
    {
      "x": 0,
      "y": 10,
      "z": 1,
      "color": "#9a9a9a"
    },
    {
      "x": 0,
      "y": 10,
      "z": 2,
      "color": "#4a6a8a"
    },
    {
      "x": 0,
      "y": 10,
      "z": 3,
      "color": "#4a6a8a"
    },
    {
      "x": 0,
      "y": 10,
      "z": 4,
      "color": "#8a8a8a"
    },
    {
      "x": 0,
      "y": 10,
      "z": 5,
      "color": "#6a6a6a"
    },
    {
      "x": 0,
      "y": 10,
      "z": 6,
      "color": "#9a9a9a"
    },
    {
      "x": 0,
      "y": 10,
      "z": 7,
      "color": "#8a8a8a"
    },
    {
      "x": 0,
      "y": 10,
      "z": 8,
      "color": "#8a8a8a"
    },
    {
      "x": 0,
      "y": 10,
      "z": 9,
      "color": "#8a8a8a"
    },
    {
      "x": 0,
      "y": 10,
      "z": 10,
      "color": "#4a6a8a"
    },
    {
      "x": 0,
      "y": 10,
      "z": 11,
      "color": "#4a6a8a"
    },
    {
      "x": 0,
      "y": 10,
      "z": 12,
      "color": "#8a8a8a"
    },
    {
      "x": 0,
      "y": 10,
      "z": 13,
      "color": "#8a8a8a"
    },
    {
      "x": 0,
      "y": 10,
      "z": 14,
      "color": "#8a8a8a"
    },
    {
      "x": 0,
      "y": 10,
      "z": 15,
      "color": "#6a6a6a"
    },
    {
      "x": 0,
      "y": 11,
      "z": 0,
      "color": "#9a9a9a"
    },
    {
      "x": 0,
      "y": 11,
      "z": 1,
      "color": "#8a8a8a"
    },
    {
      "x": 0,
      "y": 11,
      "z": 2,
      "color": "#8a8a8a"
    },
    {
      "x": 0,
      "y": 11,
      "z": 3,
      "color": "#8a8a8a"
    },
    {
      "x": 0,
      "y": 11,
      "z": 4,
      "color": "#6a6a6a"
    },
    {
      "x": 0,
      "y": 11,
      "z": 5,
      "color": "#9a9a9a"
    },
    {
      "x": 0,
      "y": 11,
      "z": 6,
      "color": "#8a8a8a"
    },
    {
      "x": 0,
      "y": 11,
      "z": 7,
      "color": "#8a8a8a"
    },
    {
      "x": 0,
      "y": 11,
      "z": 8,
      "color": "#8a8a8a"
    },
    {
      "x": 0,
      "y": 11,
      "z": 9,
      "color": "#6a6a6a"
    },
    {
      "x": 0,
      "y": 11,
      "z": 10,
      "color": "#9a9a9a"
    },
    {
      "x": 0,
      "y": 11,
      "z": 11,
      "color": "#8a8a8a"
    },
    {
      "x": 0,
      "y": 11,
      "z": 12,
      "color": "#8a8a8a"
    },
    {
      "x": 0,
      "y": 11,
      "z": 13,
      "color": "#8a8a8a"
    },
    {
      "x": 0,
      "y": 11,
      "z": 14,
      "color": "#6a6a6a"
    },
    {
      "x": 0,
      "y": 11,
      "z": 15,
      "color": "#9a9a9a"
    },
    {
      "x": 0,
      "y": 12,
      "z": 0,
      "color": "#8a8a8a"
    },
    {
      "x": 0,
      "y": 12,
      "z": 1,
      "color": "#8a8a8a"
    },
    {
      "x": 0,
      "y": 12,
      "z": 2,
      "color": "#8a8a8a"
    },
    {
      "x": 0,
      "y": 12,
      "z": 3,
      "color": "#6a6a6a"
    },
    {
      "x": 0,
      "y": 12,
      "z": 4,
      "color": "#9a9a9a"
    },
    {
      "x": 0,
      "y": 12,
      "z": 5,
      "color": "#8a8a8a"
    },
    {
      "x": 0,
      "y": 12,
      "z": 6,
      "color": "#8a8a8a"
    },
    {
      "x": 0,
      "y": 12,
      "z": 7,
      "color": "#8a8a8a"
    },
    {
      "x": 0,
      "y": 12,
      "z": 8,
      "color": "#6a6a6a"
    },
    {
      "x": 0,
      "y": 12,
      "z": 9,
      "color": "#9a9a9a"
    },
    {
      "x": 0,
      "y": 12,
      "z": 10,
      "color": "#8a8a8a"
    },
    {
      "x": 0,
      "y": 12,
      "z": 11,
      "color": "#8a8a8a"
    },
    {
      "x": 0,
      "y": 12,
      "z": 12,
      "color": "#8a8a8a"
    },
    {
      "x": 0,
      "y": 12,
      "z": 13,
      "color": "#6a6a6a"
    },
    {
      "x": 0,
      "y": 12,
      "z": 14,
      "color": "#9a9a9a"
    },
    {
      "x": 0,
      "y": 12,
      "z": 15,
      "color": "#8a8a8a"
    },
    {
      "x": 0,
      "y": 13,
      "z": 0,
      "color": "#8a8a8a"
    },
    {
      "x": 0,
      "y": 13,
      "z": 1,
      "color": "#8a8a8a"
    },
    {
      "x": 0,
      "y": 13,
      "z": 2,
      "color": "#6a6a6a"
    },
    {
      "x": 0,
      "y": 13,
      "z": 3,
      "color": "#9a9a9a"
    },
    {
      "x": 0,
      "y": 13,
      "z": 4,
      "color": "#8a8a8a"
    },
    {
      "x": 0,
      "y": 13,
      "z": 5,
      "color": "#8a8a8a"
    },
    {
      "x": 0,
      "y": 13,
      "z": 6,
      "color": "#8a8a8a"
    },
    {
      "x": 0,
      "y": 13,
      "z": 7,
      "color": "#6a6a6a"
    },
    {
      "x": 0,
      "y": 13,
      "z": 8,
      "color": "#9a9a9a"
    },
    {
      "x": 0,
      "y": 13,
      "z": 9,
      "color": "#8a8a8a"
    },
    {
      "x": 0,
      "y": 13,
      "z": 10,
      "color": "#8a8a8a"
    },
    {
      "x": 0,
      "y": 13,
      "z": 11,
      "color": "#8a8a8a"
    },
    {
      "x": 0,
      "y": 13,
      "z": 12,
      "color": "#6a6a6a"
    },
    {
      "x": 0,
      "y": 13,
      "z": 13,
      "color": "#9a9a9a"
    },
    {
      "x": 0,
      "y": 13,
      "z": 14,
      "color": "#8a8a8a"
    },
    {
      "x": 0,
      "y": 13,
      "z": 15,
      "color": "#8a8a8a"
    },
    {
      "x": 0,
      "y": 14,
      "z": 0,
      "color": "#8a8a8a"
    },
    {
      "x": 0,
      "y": 14,
      "z": 1,
      "color": "#6a6a6a"
    },
    {
      "x": 0,
      "y": 14,
      "z": 2,
      "color": "#9a9a9a"
    },
    {
      "x": 0,
      "y": 14,
      "z": 3,
      "color": "#8a8a8a"
    },
    {
      "x": 0,
      "y": 14,
      "z": 4,
      "color": "#8a8a8a"
    },
    {
      "x": 0,
      "y": 14,
      "z": 5,
      "color": "#8a8a8a"
    },
    {
      "x": 0,
      "y": 14,
      "z": 6,
      "color": "#6a6a6a"
    },
    {
      "x": 0,
      "y": 14,
      "z": 7,
      "color": "#9a9a9a"
    },
    {
      "x": 0,
      "y": 14,
      "z": 8,
      "color": "#8a8a8a"
    },
    {
      "x": 0,
      "y": 14,
      "z": 9,
      "color": "#8a8a8a"
    },
    {
      "x": 0,
      "y": 14,
      "z": 10,
      "color": "#8a8a8a"
    },
    {
      "x": 0,
      "y": 14,
      "z": 11,
      "color": "#6a6a6a"
    },
    {
      "x": 0,
      "y": 14,
      "z": 12,
      "color": "#9a9a9a"
    },
    {
      "x": 0,
      "y": 14,
      "z": 13,
      "color": "#8a8a8a"
    },
    {
      "x": 0,
      "y": 14,
      "z": 14,
      "color": "#8a8a8a"
    },
    {
      "x": 0,
      "y": 14,
      "z": 15,
      "color": "#8a8a8a"
    },
    {
      "x": 0,
      "y": 15,
      "z": 0,
      "color": "#6a6a6a"
    },
    {
      "x": 0,
      "y": 15,
      "z": 1,
      "color": "#9a9a9a"
    },
    {
      "x": 0,
      "y": 15,
      "z": 2,
      "color": "#4a6a8a"
    },
    {
      "x": 0,
      "y": 15,
      "z": 3,
      "color": "#4a6a8a"
    },
    {
      "x": 0,
      "y": 15,
      "z": 4,
      "color": "#8a8a8a"
    },
    {
      "x": 0,
      "y": 15,
      "z": 5,
      "color": "#6a6a6a"
    },
    {
      "x": 0,
      "y": 15,
      "z": 6,
      "color": "#9a9a9a"
    },
    {
      "x": 0,
      "y": 15,
      "z": 7,
      "color": "#8a8a8a"
    },
    {
      "x": 0,
      "y": 15,
      "z": 8,
      "color": "#8a8a8a"
    },
    {
      "x": 0,
      "y": 15,
      "z": 9,
      "color": "#8a8a8a"
    },
    {
      "x": 0,
      "y": 15,
      "z": 10,
      "color": "#4a6a8a"
    },
    {
      "x": 0,
      "y": 15,
      "z": 11,
      "color": "#4a6a8a"
    },
    {
      "x": 0,
      "y": 15,
      "z": 12,
      "color": "#8a8a8a"
    },
    {
      "x": 0,
      "y": 15,
      "z": 13,
      "color": "#8a8a8a"
    },
    {
      "x": 0,
      "y": 15,
      "z": 14,
      "color": "#8a8a8a"
    },
    {
      "x": 0,
      "y": 15,
      "z": 15,
      "color": "#6a6a6a"
    },
    {
      "x": 1,
      "y": 0,
      "z": 0,
      "color": "#9a9a9a"
    },
    {
      "x": 1,
      "y": 0,
      "z": 15,
      "color": "#9a9a9a"
    },
    {
      "x": 1,
      "y": 1,
      "z": 0,
      "color": "#8a8a8a"
    },
    {
      "x": 1,
      "y": 1,
      "z": 15,
      "color": "#8a8a8a"
    },
    {
      "x": 1,
      "y": 2,
      "z": 0,
      "color": "#8a8a8a"
    },
    {
      "x": 1,
      "y": 2,
      "z": 15,
      "color": "#8a8a8a"
    },
    {
      "x": 1,
      "y": 3,
      "z": 0,
      "color": "#8a8a8a"
    },
    {
      "x": 1,
      "y": 3,
      "z": 15,
      "color": "#8a8a8a"
    },
    {
      "x": 1,
      "y": 4,
      "z": 0,
      "color": "#6a6a6a"
    },
    {
      "x": 1,
      "y": 4,
      "z": 15,
      "color": "#6a6a6a"
    },
    {
      "x": 1,
      "y": 5,
      "z": 0,
      "color": "#9a9a9a"
    },
    {
      "x": 1,
      "y": 5,
      "z": 15,
      "color": "#9a9a9a"
    },
    {
      "x": 1,
      "y": 6,
      "z": 0,
      "color": "#8a8a8a"
    },
    {
      "x": 1,
      "y": 6,
      "z": 15,
      "color": "#8a8a8a"
    },
    {
      "x": 1,
      "y": 7,
      "z": 0,
      "color": "#8a8a8a"
    },
    {
      "x": 1,
      "y": 7,
      "z": 15,
      "color": "#8a8a8a"
    },
    {
      "x": 1,
      "y": 8,
      "z": 0,
      "color": "#8a8a8a"
    },
    {
      "x": 1,
      "y": 8,
      "z": 15,
      "color": "#8a8a8a"
    },
    {
      "x": 1,
      "y": 9,
      "z": 0,
      "color": "#6a6a6a"
    },
    {
      "x": 1,
      "y": 9,
      "z": 15,
      "color": "#6a6a6a"
    },
    {
      "x": 1,
      "y": 10,
      "z": 0,
      "color": "#9a9a9a"
    },
    {
      "x": 1,
      "y": 10,
      "z": 15,
      "color": "#9a9a9a"
    },
    {
      "x": 1,
      "y": 11,
      "z": 0,
      "color": "#8a8a8a"
    },
    {
      "x": 1,
      "y": 11,
      "z": 15,
      "color": "#8a8a8a"
    },
    {
      "x": 1,
      "y": 12,
      "z": 0,
      "color": "#8a8a8a"
    },
    {
      "x": 1,
      "y": 12,
      "z": 15,
      "color": "#8a8a8a"
    },
    {
      "x": 1,
      "y": 13,
      "z": 0,
      "color": "#8a8a8a"
    },
    {
      "x": 1,
      "y": 13,
      "z": 15,
      "color": "#8a8a8a"
    },
    {
      "x": 1,
      "y": 14,
      "z": 0,
      "color": "#6a6a6a"
    },
    {
      "x": 1,
      "y": 14,
      "z": 15,
      "color": "#6a6a6a"
    },
    {
      "x": 1,
      "y": 15,
      "z": 0,
      "color": "#9a9a9a"
    },
    {
      "x": 1,
      "y": 15,
      "z": 15,
      "color": "#9a9a9a"
    },
    {
      "x": 2,
      "y": 0,
      "z": 0,
      "color": "#8a8a8a"
    },
    {
      "x": 2,
      "y": 0,
      "z": 15,
      "color": "#8a8a8a"
    },
    {
      "x": 2,
      "y": 1,
      "z": 0,
      "color": "#8a8a8a"
    },
    {
      "x": 2,
      "y": 1,
      "z": 15,
      "color": "#8a8a8a"
    },
    {
      "x": 2,
      "y": 2,
      "z": 0,
      "color": "#8a8a8a"
    },
    {
      "x": 2,
      "y": 2,
      "z": 15,
      "color": "#8a8a8a"
    },
    {
      "x": 2,
      "y": 3,
      "z": 0,
      "color": "#4a6a8a"
    },
    {
      "x": 2,
      "y": 3,
      "z": 15,
      "color": "#4a6a8a"
    },
    {
      "x": 2,
      "y": 4,
      "z": 0,
      "color": "#4a6a8a"
    },
    {
      "x": 2,
      "y": 4,
      "z": 15,
      "color": "#4a6a8a"
    },
    {
      "x": 2,
      "y": 5,
      "z": 0,
      "color": "#8a8a8a"
    },
    {
      "x": 2,
      "y": 5,
      "z": 15,
      "color": "#8a8a8a"
    },
    {
      "x": 2,
      "y": 6,
      "z": 0,
      "color": "#8a8a8a"
    },
    {
      "x": 2,
      "y": 6,
      "z": 15,
      "color": "#8a8a8a"
    },
    {
      "x": 2,
      "y": 7,
      "z": 0,
      "color": "#8a8a8a"
    },
    {
      "x": 2,
      "y": 7,
      "z": 15,
      "color": "#8a8a8a"
    },
    {
      "x": 2,
      "y": 8,
      "z": 0,
      "color": "#6a6a6a"
    },
    {
      "x": 2,
      "y": 8,
      "z": 15,
      "color": "#6a6a6a"
    },
    {
      "x": 2,
      "y": 9,
      "z": 0,
      "color": "#4a6a8a"
    },
    {
      "x": 2,
      "y": 9,
      "z": 15,
      "color": "#4a6a8a"
    },
    {
      "x": 2,
      "y": 10,
      "z": 0,
      "color": "#4a6a8a"
    },
    {
      "x": 2,
      "y": 10,
      "z": 15,
      "color": "#4a6a8a"
    },
    {
      "x": 2,
      "y": 11,
      "z": 0,
      "color": "#8a8a8a"
    },
    {
      "x": 2,
      "y": 11,
      "z": 15,
      "color": "#8a8a8a"
    },
    {
      "x": 2,
      "y": 12,
      "z": 0,
      "color": "#8a8a8a"
    },
    {
      "x": 2,
      "y": 12,
      "z": 15,
      "color": "#8a8a8a"
    },
    {
      "x": 2,
      "y": 13,
      "z": 0,
      "color": "#6a6a6a"
    },
    {
      "x": 2,
      "y": 13,
      "z": 15,
      "color": "#6a6a6a"
    },
    {
      "x": 2,
      "y": 14,
      "z": 0,
      "color": "#9a9a9a"
    },
    {
      "x": 2,
      "y": 14,
      "z": 15,
      "color": "#9a9a9a"
    },
    {
      "x": 2,
      "y": 15,
      "z": 0,
      "color": "#4a6a8a"
    },
    {
      "x": 2,
      "y": 15,
      "z": 15,
      "color": "#4a6a8a"
    },
    {
      "x": 3,
      "y": 0,
      "z": 0,
      "color": "#8a8a8a"
    },
    {
      "x": 3,
      "y": 0,
      "z": 15,
      "color": "#8a8a8a"
    },
    {
      "x": 3,
      "y": 1,
      "z": 0,
      "color": "#8a8a8a"
    },
    {
      "x": 3,
      "y": 1,
      "z": 15,
      "color": "#8a8a8a"
    },
    {
      "x": 3,
      "y": 2,
      "z": 0,
      "color": "#6a6a6a"
    },
    {
      "x": 3,
      "y": 2,
      "z": 15,
      "color": "#6a6a6a"
    },
    {
      "x": 3,
      "y": 3,
      "z": 0,
      "color": "#4a6a8a"
    },
    {
      "x": 3,
      "y": 3,
      "z": 15,
      "color": "#4a6a8a"
    },
    {
      "x": 3,
      "y": 4,
      "z": 0,
      "color": "#4a6a8a"
    },
    {
      "x": 3,
      "y": 4,
      "z": 15,
      "color": "#4a6a8a"
    },
    {
      "x": 3,
      "y": 5,
      "z": 0,
      "color": "#8a8a8a"
    },
    {
      "x": 3,
      "y": 5,
      "z": 15,
      "color": "#8a8a8a"
    },
    {
      "x": 3,
      "y": 6,
      "z": 0,
      "color": "#8a8a8a"
    },
    {
      "x": 3,
      "y": 6,
      "z": 15,
      "color": "#8a8a8a"
    },
    {
      "x": 3,
      "y": 7,
      "z": 0,
      "color": "#6a6a6a"
    },
    {
      "x": 3,
      "y": 7,
      "z": 15,
      "color": "#6a6a6a"
    },
    {
      "x": 3,
      "y": 8,
      "z": 0,
      "color": "#9a9a9a"
    },
    {
      "x": 3,
      "y": 8,
      "z": 15,
      "color": "#9a9a9a"
    },
    {
      "x": 3,
      "y": 9,
      "z": 0,
      "color": "#4a6a8a"
    },
    {
      "x": 3,
      "y": 9,
      "z": 15,
      "color": "#4a6a8a"
    },
    {
      "x": 3,
      "y": 10,
      "z": 0,
      "color": "#4a6a8a"
    },
    {
      "x": 3,
      "y": 10,
      "z": 15,
      "color": "#4a6a8a"
    },
    {
      "x": 3,
      "y": 11,
      "z": 0,
      "color": "#8a8a8a"
    },
    {
      "x": 3,
      "y": 11,
      "z": 15,
      "color": "#8a8a8a"
    },
    {
      "x": 3,
      "y": 12,
      "z": 0,
      "color": "#6a6a6a"
    },
    {
      "x": 3,
      "y": 12,
      "z": 15,
      "color": "#6a6a6a"
    },
    {
      "x": 3,
      "y": 13,
      "z": 0,
      "color": "#9a9a9a"
    },
    {
      "x": 3,
      "y": 13,
      "z": 15,
      "color": "#9a9a9a"
    },
    {
      "x": 3,
      "y": 14,
      "z": 0,
      "color": "#8a8a8a"
    },
    {
      "x": 3,
      "y": 14,
      "z": 15,
      "color": "#8a8a8a"
    },
    {
      "x": 3,
      "y": 15,
      "z": 0,
      "color": "#4a6a8a"
    },
    {
      "x": 3,
      "y": 15,
      "z": 15,
      "color": "#4a6a8a"
    },
    {
      "x": 4,
      "y": 0,
      "z": 0,
      "color": "#8a8a8a"
    },
    {
      "x": 4,
      "y": 0,
      "z": 15,
      "color": "#8a8a8a"
    },
    {
      "x": 4,
      "y": 1,
      "z": 0,
      "color": "#6a6a6a"
    },
    {
      "x": 4,
      "y": 1,
      "z": 15,
      "color": "#6a6a6a"
    },
    {
      "x": 4,
      "y": 2,
      "z": 0,
      "color": "#9a9a9a"
    },
    {
      "x": 4,
      "y": 2,
      "z": 15,
      "color": "#9a9a9a"
    },
    {
      "x": 4,
      "y": 3,
      "z": 0,
      "color": "#8a8a8a"
    },
    {
      "x": 4,
      "y": 3,
      "z": 15,
      "color": "#8a8a8a"
    },
    {
      "x": 4,
      "y": 4,
      "z": 0,
      "color": "#8a8a8a"
    },
    {
      "x": 4,
      "y": 4,
      "z": 15,
      "color": "#8a8a8a"
    },
    {
      "x": 4,
      "y": 5,
      "z": 0,
      "color": "#8a8a8a"
    },
    {
      "x": 4,
      "y": 5,
      "z": 15,
      "color": "#8a8a8a"
    },
    {
      "x": 4,
      "y": 6,
      "z": 0,
      "color": "#6a6a6a"
    },
    {
      "x": 4,
      "y": 6,
      "z": 15,
      "color": "#6a6a6a"
    },
    {
      "x": 4,
      "y": 7,
      "z": 0,
      "color": "#9a9a9a"
    },
    {
      "x": 4,
      "y": 7,
      "z": 15,
      "color": "#9a9a9a"
    },
    {
      "x": 4,
      "y": 8,
      "z": 0,
      "color": "#8a8a8a"
    },
    {
      "x": 4,
      "y": 8,
      "z": 15,
      "color": "#8a8a8a"
    },
    {
      "x": 4,
      "y": 9,
      "z": 0,
      "color": "#8a8a8a"
    },
    {
      "x": 4,
      "y": 9,
      "z": 15,
      "color": "#8a8a8a"
    },
    {
      "x": 4,
      "y": 10,
      "z": 0,
      "color": "#8a8a8a"
    },
    {
      "x": 4,
      "y": 10,
      "z": 15,
      "color": "#8a8a8a"
    },
    {
      "x": 4,
      "y": 11,
      "z": 0,
      "color": "#6a6a6a"
    },
    {
      "x": 4,
      "y": 11,
      "z": 15,
      "color": "#6a6a6a"
    },
    {
      "x": 4,
      "y": 12,
      "z": 0,
      "color": "#9a9a9a"
    },
    {
      "x": 4,
      "y": 12,
      "z": 15,
      "color": "#9a9a9a"
    },
    {
      "x": 4,
      "y": 13,
      "z": 0,
      "color": "#8a8a8a"
    },
    {
      "x": 4,
      "y": 13,
      "z": 15,
      "color": "#8a8a8a"
    },
    {
      "x": 4,
      "y": 14,
      "z": 0,
      "color": "#8a8a8a"
    },
    {
      "x": 4,
      "y": 14,
      "z": 15,
      "color": "#8a8a8a"
    },
    {
      "x": 4,
      "y": 15,
      "z": 0,
      "color": "#8a8a8a"
    },
    {
      "x": 4,
      "y": 15,
      "z": 15,
      "color": "#8a8a8a"
    },
    {
      "x": 5,
      "y": 0,
      "z": 0,
      "color": "#6a6a6a"
    },
    {
      "x": 5,
      "y": 0,
      "z": 15,
      "color": "#6a6a6a"
    },
    {
      "x": 5,
      "y": 1,
      "z": 0,
      "color": "#9a9a9a"
    },
    {
      "x": 5,
      "y": 1,
      "z": 15,
      "color": "#9a9a9a"
    },
    {
      "x": 5,
      "y": 2,
      "z": 0,
      "color": "#8a8a8a"
    },
    {
      "x": 5,
      "y": 2,
      "z": 15,
      "color": "#8a8a8a"
    },
    {
      "x": 5,
      "y": 3,
      "z": 0,
      "color": "#8a8a8a"
    },
    {
      "x": 5,
      "y": 3,
      "z": 15,
      "color": "#8a8a8a"
    },
    {
      "x": 5,
      "y": 4,
      "z": 0,
      "color": "#8a8a8a"
    },
    {
      "x": 5,
      "y": 4,
      "z": 15,
      "color": "#8a8a8a"
    },
    {
      "x": 5,
      "y": 5,
      "z": 0,
      "color": "#6a6a6a"
    },
    {
      "x": 5,
      "y": 5,
      "z": 15,
      "color": "#6a6a6a"
    },
    {
      "x": 5,
      "y": 6,
      "z": 0,
      "color": "#9a9a9a"
    },
    {
      "x": 5,
      "y": 6,
      "z": 15,
      "color": "#9a9a9a"
    },
    {
      "x": 5,
      "y": 7,
      "z": 0,
      "color": "#8a8a8a"
    },
    {
      "x": 5,
      "y": 7,
      "z": 15,
      "color": "#8a8a8a"
    },
    {
      "x": 5,
      "y": 8,
      "z": 0,
      "color": "#8a8a8a"
    },
    {
      "x": 5,
      "y": 8,
      "z": 15,
      "color": "#8a8a8a"
    },
    {
      "x": 5,
      "y": 9,
      "z": 0,
      "color": "#8a8a8a"
    },
    {
      "x": 5,
      "y": 9,
      "z": 15,
      "color": "#8a8a8a"
    },
    {
      "x": 5,
      "y": 10,
      "z": 0,
      "color": "#6a6a6a"
    },
    {
      "x": 5,
      "y": 10,
      "z": 15,
      "color": "#6a6a6a"
    },
    {
      "x": 5,
      "y": 11,
      "z": 0,
      "color": "#9a9a9a"
    },
    {
      "x": 5,
      "y": 11,
      "z": 15,
      "color": "#9a9a9a"
    },
    {
      "x": 5,
      "y": 12,
      "z": 0,
      "color": "#8a8a8a"
    },
    {
      "x": 5,
      "y": 12,
      "z": 15,
      "color": "#8a8a8a"
    },
    {
      "x": 5,
      "y": 13,
      "z": 0,
      "color": "#8a8a8a"
    },
    {
      "x": 5,
      "y": 13,
      "z": 15,
      "color": "#8a8a8a"
    },
    {
      "x": 5,
      "y": 14,
      "z": 0,
      "color": "#8a8a8a"
    },
    {
      "x": 5,
      "y": 14,
      "z": 15,
      "color": "#8a8a8a"
    },
    {
      "x": 5,
      "y": 15,
      "z": 0,
      "color": "#6a6a6a"
    },
    {
      "x": 5,
      "y": 15,
      "z": 15,
      "color": "#6a6a6a"
    },
    {
      "x": 6,
      "y": 0,
      "z": 0,
      "color": "#9a9a9a"
    },
    {
      "x": 6,
      "y": 0,
      "z": 15,
      "color": "#9a9a9a"
    },
    {
      "x": 6,
      "y": 1,
      "z": 0,
      "color": "#8a8a8a"
    },
    {
      "x": 6,
      "y": 1,
      "z": 15,
      "color": "#8a8a8a"
    },
    {
      "x": 6,
      "y": 2,
      "z": 0,
      "color": "#8a8a8a"
    },
    {
      "x": 6,
      "y": 2,
      "z": 15,
      "color": "#8a8a8a"
    },
    {
      "x": 6,
      "y": 3,
      "z": 0,
      "color": "#8a8a8a"
    },
    {
      "x": 6,
      "y": 3,
      "z": 15,
      "color": "#8a8a8a"
    },
    {
      "x": 6,
      "y": 4,
      "z": 0,
      "color": "#6a6a6a"
    },
    {
      "x": 6,
      "y": 4,
      "z": 15,
      "color": "#6a6a6a"
    },
    {
      "x": 6,
      "y": 5,
      "z": 0,
      "color": "#9a9a9a"
    },
    {
      "x": 6,
      "y": 5,
      "z": 15,
      "color": "#9a9a9a"
    },
    {
      "x": 6,
      "y": 6,
      "z": 0,
      "color": "#8a8a8a"
    },
    {
      "x": 6,
      "y": 6,
      "z": 15,
      "color": "#8a8a8a"
    },
    {
      "x": 6,
      "y": 7,
      "z": 0,
      "color": "#8a8a8a"
    },
    {
      "x": 6,
      "y": 7,
      "z": 15,
      "color": "#8a8a8a"
    },
    {
      "x": 6,
      "y": 8,
      "z": 0,
      "color": "#8a8a8a"
    },
    {
      "x": 6,
      "y": 8,
      "z": 15,
      "color": "#8a8a8a"
    },
    {
      "x": 6,
      "y": 9,
      "z": 0,
      "color": "#6a6a6a"
    },
    {
      "x": 6,
      "y": 9,
      "z": 15,
      "color": "#6a6a6a"
    },
    {
      "x": 6,
      "y": 10,
      "z": 0,
      "color": "#9a9a9a"
    },
    {
      "x": 6,
      "y": 10,
      "z": 15,
      "color": "#9a9a9a"
    },
    {
      "x": 6,
      "y": 11,
      "z": 0,
      "color": "#8a8a8a"
    },
    {
      "x": 6,
      "y": 11,
      "z": 15,
      "color": "#8a8a8a"
    },
    {
      "x": 6,
      "y": 12,
      "z": 0,
      "color": "#8a8a8a"
    },
    {
      "x": 6,
      "y": 12,
      "z": 15,
      "color": "#8a8a8a"
    },
    {
      "x": 6,
      "y": 13,
      "z": 0,
      "color": "#8a8a8a"
    },
    {
      "x": 6,
      "y": 13,
      "z": 15,
      "color": "#8a8a8a"
    },
    {
      "x": 6,
      "y": 14,
      "z": 0,
      "color": "#6a6a6a"
    },
    {
      "x": 6,
      "y": 14,
      "z": 15,
      "color": "#6a6a6a"
    },
    {
      "x": 6,
      "y": 15,
      "z": 0,
      "color": "#9a9a9a"
    },
    {
      "x": 6,
      "y": 15,
      "z": 15,
      "color": "#9a9a9a"
    },
    {
      "x": 7,
      "y": 0,
      "z": 0,
      "color": "#8a8a8a"
    },
    {
      "x": 7,
      "y": 0,
      "z": 15,
      "color": "#8a8a8a"
    },
    {
      "x": 7,
      "y": 1,
      "z": 0,
      "color": "#8a8a8a"
    },
    {
      "x": 7,
      "y": 1,
      "z": 15,
      "color": "#8a8a8a"
    },
    {
      "x": 7,
      "y": 2,
      "z": 0,
      "color": "#8a8a8a"
    },
    {
      "x": 7,
      "y": 2,
      "z": 15,
      "color": "#8a8a8a"
    },
    {
      "x": 7,
      "y": 3,
      "z": 0,
      "color": "#6a6a6a"
    },
    {
      "x": 7,
      "y": 3,
      "z": 15,
      "color": "#6a6a6a"
    },
    {
      "x": 7,
      "y": 4,
      "z": 0,
      "color": "#9a9a9a"
    },
    {
      "x": 7,
      "y": 4,
      "z": 15,
      "color": "#9a9a9a"
    },
    {
      "x": 7,
      "y": 5,
      "z": 0,
      "color": "#8a8a8a"
    },
    {
      "x": 7,
      "y": 5,
      "z": 15,
      "color": "#8a8a8a"
    },
    {
      "x": 7,
      "y": 6,
      "z": 0,
      "color": "#8a8a8a"
    },
    {
      "x": 7,
      "y": 6,
      "z": 15,
      "color": "#8a8a8a"
    },
    {
      "x": 7,
      "y": 7,
      "z": 0,
      "color": "#8a8a8a"
    },
    {
      "x": 7,
      "y": 7,
      "z": 15,
      "color": "#8a8a8a"
    },
    {
      "x": 7,
      "y": 8,
      "z": 0,
      "color": "#6a6a6a"
    },
    {
      "x": 7,
      "y": 8,
      "z": 15,
      "color": "#6a6a6a"
    },
    {
      "x": 7,
      "y": 9,
      "z": 0,
      "color": "#9a9a9a"
    },
    {
      "x": 7,
      "y": 9,
      "z": 15,
      "color": "#9a9a9a"
    },
    {
      "x": 7,
      "y": 10,
      "z": 0,
      "color": "#8a8a8a"
    },
    {
      "x": 7,
      "y": 10,
      "z": 15,
      "color": "#8a8a8a"
    },
    {
      "x": 7,
      "y": 11,
      "z": 0,
      "color": "#8a8a8a"
    },
    {
      "x": 7,
      "y": 11,
      "z": 15,
      "color": "#8a8a8a"
    },
    {
      "x": 7,
      "y": 12,
      "z": 0,
      "color": "#8a8a8a"
    },
    {
      "x": 7,
      "y": 12,
      "z": 15,
      "color": "#8a8a8a"
    },
    {
      "x": 7,
      "y": 13,
      "z": 0,
      "color": "#6a6a6a"
    },
    {
      "x": 7,
      "y": 13,
      "z": 15,
      "color": "#6a6a6a"
    },
    {
      "x": 7,
      "y": 14,
      "z": 0,
      "color": "#9a9a9a"
    },
    {
      "x": 7,
      "y": 14,
      "z": 15,
      "color": "#9a9a9a"
    },
    {
      "x": 7,
      "y": 15,
      "z": 0,
      "color": "#8a8a8a"
    },
    {
      "x": 7,
      "y": 15,
      "z": 15,
      "color": "#8a8a8a"
    },
    {
      "x": 8,
      "y": 0,
      "z": 0,
      "color": "#8a8a8a"
    },
    {
      "x": 8,
      "y": 0,
      "z": 15,
      "color": "#8a8a8a"
    },
    {
      "x": 8,
      "y": 1,
      "z": 0,
      "color": "#8a8a8a"
    },
    {
      "x": 8,
      "y": 1,
      "z": 15,
      "color": "#8a8a8a"
    },
    {
      "x": 8,
      "y": 2,
      "z": 0,
      "color": "#6a6a6a"
    },
    {
      "x": 8,
      "y": 2,
      "z": 15,
      "color": "#6a6a6a"
    },
    {
      "x": 8,
      "y": 3,
      "z": 0,
      "color": "#9a9a9a"
    },
    {
      "x": 8,
      "y": 3,
      "z": 15,
      "color": "#9a9a9a"
    },
    {
      "x": 8,
      "y": 4,
      "z": 0,
      "color": "#8a8a8a"
    },
    {
      "x": 8,
      "y": 4,
      "z": 15,
      "color": "#8a8a8a"
    },
    {
      "x": 8,
      "y": 5,
      "z": 0,
      "color": "#8a8a8a"
    },
    {
      "x": 8,
      "y": 5,
      "z": 15,
      "color": "#8a8a8a"
    },
    {
      "x": 8,
      "y": 6,
      "z": 0,
      "color": "#8a8a8a"
    },
    {
      "x": 8,
      "y": 6,
      "z": 15,
      "color": "#8a8a8a"
    },
    {
      "x": 8,
      "y": 7,
      "z": 0,
      "color": "#6a6a6a"
    },
    {
      "x": 8,
      "y": 7,
      "z": 15,
      "color": "#6a6a6a"
    },
    {
      "x": 8,
      "y": 8,
      "z": 0,
      "color": "#9a9a9a"
    },
    {
      "x": 8,
      "y": 8,
      "z": 15,
      "color": "#9a9a9a"
    },
    {
      "x": 8,
      "y": 9,
      "z": 0,
      "color": "#8a8a8a"
    },
    {
      "x": 8,
      "y": 9,
      "z": 15,
      "color": "#8a8a8a"
    },
    {
      "x": 8,
      "y": 10,
      "z": 0,
      "color": "#8a8a8a"
    },
    {
      "x": 8,
      "y": 10,
      "z": 15,
      "color": "#8a8a8a"
    },
    {
      "x": 8,
      "y": 11,
      "z": 0,
      "color": "#8a8a8a"
    },
    {
      "x": 8,
      "y": 11,
      "z": 15,
      "color": "#8a8a8a"
    },
    {
      "x": 8,
      "y": 12,
      "z": 0,
      "color": "#6a6a6a"
    },
    {
      "x": 8,
      "y": 12,
      "z": 15,
      "color": "#6a6a6a"
    },
    {
      "x": 8,
      "y": 13,
      "z": 0,
      "color": "#9a9a9a"
    },
    {
      "x": 8,
      "y": 13,
      "z": 15,
      "color": "#9a9a9a"
    },
    {
      "x": 8,
      "y": 14,
      "z": 0,
      "color": "#8a8a8a"
    },
    {
      "x": 8,
      "y": 14,
      "z": 15,
      "color": "#8a8a8a"
    },
    {
      "x": 8,
      "y": 15,
      "z": 0,
      "color": "#8a8a8a"
    },
    {
      "x": 8,
      "y": 15,
      "z": 15,
      "color": "#8a8a8a"
    },
    {
      "x": 9,
      "y": 0,
      "z": 0,
      "color": "#8a8a8a"
    },
    {
      "x": 9,
      "y": 0,
      "z": 15,
      "color": "#8a8a8a"
    },
    {
      "x": 9,
      "y": 1,
      "z": 0,
      "color": "#6a6a6a"
    },
    {
      "x": 9,
      "y": 1,
      "z": 15,
      "color": "#6a6a6a"
    },
    {
      "x": 9,
      "y": 2,
      "z": 0,
      "color": "#9a9a9a"
    },
    {
      "x": 9,
      "y": 2,
      "z": 15,
      "color": "#9a9a9a"
    },
    {
      "x": 9,
      "y": 3,
      "z": 0,
      "color": "#8a8a8a"
    },
    {
      "x": 9,
      "y": 3,
      "z": 15,
      "color": "#8a8a8a"
    },
    {
      "x": 9,
      "y": 4,
      "z": 0,
      "color": "#8a8a8a"
    },
    {
      "x": 9,
      "y": 4,
      "z": 15,
      "color": "#8a8a8a"
    },
    {
      "x": 9,
      "y": 5,
      "z": 0,
      "color": "#8a8a8a"
    },
    {
      "x": 9,
      "y": 5,
      "z": 15,
      "color": "#8a8a8a"
    },
    {
      "x": 9,
      "y": 6,
      "z": 0,
      "color": "#6a6a6a"
    },
    {
      "x": 9,
      "y": 6,
      "z": 15,
      "color": "#6a6a6a"
    },
    {
      "x": 9,
      "y": 7,
      "z": 0,
      "color": "#9a9a9a"
    },
    {
      "x": 9,
      "y": 7,
      "z": 15,
      "color": "#9a9a9a"
    },
    {
      "x": 9,
      "y": 8,
      "z": 0,
      "color": "#8a8a8a"
    },
    {
      "x": 9,
      "y": 8,
      "z": 15,
      "color": "#8a8a8a"
    },
    {
      "x": 9,
      "y": 9,
      "z": 0,
      "color": "#8a8a8a"
    },
    {
      "x": 9,
      "y": 9,
      "z": 15,
      "color": "#8a8a8a"
    },
    {
      "x": 9,
      "y": 10,
      "z": 0,
      "color": "#8a8a8a"
    },
    {
      "x": 9,
      "y": 10,
      "z": 15,
      "color": "#8a8a8a"
    },
    {
      "x": 9,
      "y": 11,
      "z": 0,
      "color": "#6a6a6a"
    },
    {
      "x": 9,
      "y": 11,
      "z": 15,
      "color": "#6a6a6a"
    },
    {
      "x": 9,
      "y": 12,
      "z": 0,
      "color": "#9a9a9a"
    },
    {
      "x": 9,
      "y": 12,
      "z": 15,
      "color": "#9a9a9a"
    },
    {
      "x": 9,
      "y": 13,
      "z": 0,
      "color": "#8a8a8a"
    },
    {
      "x": 9,
      "y": 13,
      "z": 15,
      "color": "#8a8a8a"
    },
    {
      "x": 9,
      "y": 14,
      "z": 0,
      "color": "#8a8a8a"
    },
    {
      "x": 9,
      "y": 14,
      "z": 15,
      "color": "#8a8a8a"
    },
    {
      "x": 9,
      "y": 15,
      "z": 0,
      "color": "#8a8a8a"
    },
    {
      "x": 9,
      "y": 15,
      "z": 15,
      "color": "#8a8a8a"
    },
    {
      "x": 10,
      "y": 0,
      "z": 0,
      "color": "#6a6a6a"
    },
    {
      "x": 10,
      "y": 0,
      "z": 15,
      "color": "#6a6a6a"
    },
    {
      "x": 10,
      "y": 1,
      "z": 0,
      "color": "#9a9a9a"
    },
    {
      "x": 10,
      "y": 1,
      "z": 15,
      "color": "#9a9a9a"
    },
    {
      "x": 10,
      "y": 2,
      "z": 0,
      "color": "#8a8a8a"
    },
    {
      "x": 10,
      "y": 2,
      "z": 15,
      "color": "#8a8a8a"
    },
    {
      "x": 10,
      "y": 3,
      "z": 0,
      "color": "#4a6a8a"
    },
    {
      "x": 10,
      "y": 3,
      "z": 15,
      "color": "#4a6a8a"
    },
    {
      "x": 10,
      "y": 4,
      "z": 0,
      "color": "#4a6a8a"
    },
    {
      "x": 10,
      "y": 4,
      "z": 15,
      "color": "#4a6a8a"
    },
    {
      "x": 10,
      "y": 5,
      "z": 0,
      "color": "#6a6a6a"
    },
    {
      "x": 10,
      "y": 5,
      "z": 15,
      "color": "#6a6a6a"
    },
    {
      "x": 10,
      "y": 6,
      "z": 0,
      "color": "#9a9a9a"
    },
    {
      "x": 10,
      "y": 6,
      "z": 15,
      "color": "#9a9a9a"
    },
    {
      "x": 10,
      "y": 7,
      "z": 0,
      "color": "#8a8a8a"
    },
    {
      "x": 10,
      "y": 7,
      "z": 15,
      "color": "#8a8a8a"
    },
    {
      "x": 10,
      "y": 8,
      "z": 0,
      "color": "#8a8a8a"
    },
    {
      "x": 10,
      "y": 8,
      "z": 15,
      "color": "#8a8a8a"
    },
    {
      "x": 10,
      "y": 9,
      "z": 0,
      "color": "#4a6a8a"
    },
    {
      "x": 10,
      "y": 9,
      "z": 15,
      "color": "#4a6a8a"
    },
    {
      "x": 10,
      "y": 10,
      "z": 0,
      "color": "#4a6a8a"
    },
    {
      "x": 10,
      "y": 10,
      "z": 15,
      "color": "#4a6a8a"
    },
    {
      "x": 10,
      "y": 11,
      "z": 0,
      "color": "#9a9a9a"
    },
    {
      "x": 10,
      "y": 11,
      "z": 15,
      "color": "#9a9a9a"
    },
    {
      "x": 10,
      "y": 12,
      "z": 0,
      "color": "#8a8a8a"
    },
    {
      "x": 10,
      "y": 12,
      "z": 15,
      "color": "#8a8a8a"
    },
    {
      "x": 10,
      "y": 13,
      "z": 0,
      "color": "#8a8a8a"
    },
    {
      "x": 10,
      "y": 13,
      "z": 15,
      "color": "#8a8a8a"
    },
    {
      "x": 10,
      "y": 14,
      "z": 0,
      "color": "#8a8a8a"
    },
    {
      "x": 10,
      "y": 14,
      "z": 15,
      "color": "#8a8a8a"
    },
    {
      "x": 10,
      "y": 15,
      "z": 0,
      "color": "#4a6a8a"
    },
    {
      "x": 10,
      "y": 15,
      "z": 15,
      "color": "#4a6a8a"
    },
    {
      "x": 11,
      "y": 0,
      "z": 0,
      "color": "#9a9a9a"
    },
    {
      "x": 11,
      "y": 0,
      "z": 15,
      "color": "#9a9a9a"
    },
    {
      "x": 11,
      "y": 1,
      "z": 0,
      "color": "#8a8a8a"
    },
    {
      "x": 11,
      "y": 1,
      "z": 15,
      "color": "#8a8a8a"
    },
    {
      "x": 11,
      "y": 2,
      "z": 0,
      "color": "#8a8a8a"
    },
    {
      "x": 11,
      "y": 2,
      "z": 15,
      "color": "#8a8a8a"
    },
    {
      "x": 11,
      "y": 3,
      "z": 0,
      "color": "#4a6a8a"
    },
    {
      "x": 11,
      "y": 3,
      "z": 15,
      "color": "#4a6a8a"
    },
    {
      "x": 11,
      "y": 4,
      "z": 0,
      "color": "#4a6a8a"
    },
    {
      "x": 11,
      "y": 4,
      "z": 15,
      "color": "#4a6a8a"
    },
    {
      "x": 11,
      "y": 5,
      "z": 0,
      "color": "#9a9a9a"
    },
    {
      "x": 11,
      "y": 5,
      "z": 15,
      "color": "#9a9a9a"
    },
    {
      "x": 11,
      "y": 6,
      "z": 0,
      "color": "#8a8a8a"
    },
    {
      "x": 11,
      "y": 6,
      "z": 15,
      "color": "#8a8a8a"
    },
    {
      "x": 11,
      "y": 7,
      "z": 0,
      "color": "#8a8a8a"
    },
    {
      "x": 11,
      "y": 7,
      "z": 15,
      "color": "#8a8a8a"
    },
    {
      "x": 11,
      "y": 8,
      "z": 0,
      "color": "#8a8a8a"
    },
    {
      "x": 11,
      "y": 8,
      "z": 15,
      "color": "#8a8a8a"
    },
    {
      "x": 11,
      "y": 9,
      "z": 0,
      "color": "#4a6a8a"
    },
    {
      "x": 11,
      "y": 9,
      "z": 15,
      "color": "#4a6a8a"
    },
    {
      "x": 11,
      "y": 10,
      "z": 0,
      "color": "#4a6a8a"
    },
    {
      "x": 11,
      "y": 10,
      "z": 15,
      "color": "#4a6a8a"
    },
    {
      "x": 11,
      "y": 11,
      "z": 0,
      "color": "#8a8a8a"
    },
    {
      "x": 11,
      "y": 11,
      "z": 15,
      "color": "#8a8a8a"
    },
    {
      "x": 11,
      "y": 12,
      "z": 0,
      "color": "#8a8a8a"
    },
    {
      "x": 11,
      "y": 12,
      "z": 15,
      "color": "#8a8a8a"
    },
    {
      "x": 11,
      "y": 13,
      "z": 0,
      "color": "#8a8a8a"
    },
    {
      "x": 11,
      "y": 13,
      "z": 15,
      "color": "#8a8a8a"
    },
    {
      "x": 11,
      "y": 14,
      "z": 0,
      "color": "#6a6a6a"
    },
    {
      "x": 11,
      "y": 14,
      "z": 15,
      "color": "#6a6a6a"
    },
    {
      "x": 11,
      "y": 15,
      "z": 0,
      "color": "#4a6a8a"
    },
    {
      "x": 11,
      "y": 15,
      "z": 15,
      "color": "#4a6a8a"
    },
    {
      "x": 12,
      "y": 0,
      "z": 0,
      "color": "#8a8a8a"
    },
    {
      "x": 12,
      "y": 0,
      "z": 15,
      "color": "#8a8a8a"
    },
    {
      "x": 12,
      "y": 1,
      "z": 0,
      "color": "#8a8a8a"
    },
    {
      "x": 12,
      "y": 1,
      "z": 15,
      "color": "#8a8a8a"
    },
    {
      "x": 12,
      "y": 2,
      "z": 0,
      "color": "#8a8a8a"
    },
    {
      "x": 12,
      "y": 2,
      "z": 15,
      "color": "#8a8a8a"
    },
    {
      "x": 12,
      "y": 3,
      "z": 0,
      "color": "#6a6a6a"
    },
    {
      "x": 12,
      "y": 3,
      "z": 15,
      "color": "#6a6a6a"
    },
    {
      "x": 12,
      "y": 4,
      "z": 0,
      "color": "#9a9a9a"
    },
    {
      "x": 12,
      "y": 4,
      "z": 15,
      "color": "#9a9a9a"
    },
    {
      "x": 12,
      "y": 5,
      "z": 0,
      "color": "#8a8a8a"
    },
    {
      "x": 12,
      "y": 5,
      "z": 15,
      "color": "#8a8a8a"
    },
    {
      "x": 12,
      "y": 6,
      "z": 0,
      "color": "#8a8a8a"
    },
    {
      "x": 12,
      "y": 6,
      "z": 15,
      "color": "#8a8a8a"
    },
    {
      "x": 12,
      "y": 7,
      "z": 0,
      "color": "#8a8a8a"
    },
    {
      "x": 12,
      "y": 7,
      "z": 15,
      "color": "#8a8a8a"
    },
    {
      "x": 12,
      "y": 8,
      "z": 0,
      "color": "#6a6a6a"
    },
    {
      "x": 12,
      "y": 8,
      "z": 15,
      "color": "#6a6a6a"
    },
    {
      "x": 12,
      "y": 9,
      "z": 0,
      "color": "#9a9a9a"
    },
    {
      "x": 12,
      "y": 9,
      "z": 15,
      "color": "#9a9a9a"
    },
    {
      "x": 12,
      "y": 10,
      "z": 0,
      "color": "#8a8a8a"
    },
    {
      "x": 12,
      "y": 10,
      "z": 15,
      "color": "#8a8a8a"
    },
    {
      "x": 12,
      "y": 11,
      "z": 0,
      "color": "#8a8a8a"
    },
    {
      "x": 12,
      "y": 11,
      "z": 15,
      "color": "#8a8a8a"
    },
    {
      "x": 12,
      "y": 12,
      "z": 0,
      "color": "#8a8a8a"
    },
    {
      "x": 12,
      "y": 12,
      "z": 15,
      "color": "#8a8a8a"
    },
    {
      "x": 12,
      "y": 13,
      "z": 0,
      "color": "#6a6a6a"
    },
    {
      "x": 12,
      "y": 13,
      "z": 15,
      "color": "#6a6a6a"
    },
    {
      "x": 12,
      "y": 14,
      "z": 0,
      "color": "#9a9a9a"
    },
    {
      "x": 12,
      "y": 14,
      "z": 15,
      "color": "#9a9a9a"
    },
    {
      "x": 12,
      "y": 15,
      "z": 0,
      "color": "#8a8a8a"
    },
    {
      "x": 12,
      "y": 15,
      "z": 15,
      "color": "#8a8a8a"
    },
    {
      "x": 13,
      "y": 0,
      "z": 0,
      "color": "#8a8a8a"
    },
    {
      "x": 13,
      "y": 0,
      "z": 15,
      "color": "#8a8a8a"
    },
    {
      "x": 13,
      "y": 1,
      "z": 0,
      "color": "#8a8a8a"
    },
    {
      "x": 13,
      "y": 1,
      "z": 15,
      "color": "#8a8a8a"
    },
    {
      "x": 13,
      "y": 2,
      "z": 0,
      "color": "#6a6a6a"
    },
    {
      "x": 13,
      "y": 2,
      "z": 15,
      "color": "#6a6a6a"
    },
    {
      "x": 13,
      "y": 3,
      "z": 0,
      "color": "#9a9a9a"
    },
    {
      "x": 13,
      "y": 3,
      "z": 15,
      "color": "#9a9a9a"
    },
    {
      "x": 13,
      "y": 4,
      "z": 0,
      "color": "#8a8a8a"
    },
    {
      "x": 13,
      "y": 4,
      "z": 15,
      "color": "#8a8a8a"
    },
    {
      "x": 13,
      "y": 5,
      "z": 0,
      "color": "#8a8a8a"
    },
    {
      "x": 13,
      "y": 5,
      "z": 15,
      "color": "#8a8a8a"
    },
    {
      "x": 13,
      "y": 6,
      "z": 0,
      "color": "#8a8a8a"
    },
    {
      "x": 13,
      "y": 6,
      "z": 15,
      "color": "#8a8a8a"
    },
    {
      "x": 13,
      "y": 7,
      "z": 0,
      "color": "#6a6a6a"
    },
    {
      "x": 13,
      "y": 7,
      "z": 15,
      "color": "#6a6a6a"
    },
    {
      "x": 13,
      "y": 8,
      "z": 0,
      "color": "#9a9a9a"
    },
    {
      "x": 13,
      "y": 8,
      "z": 15,
      "color": "#9a9a9a"
    },
    {
      "x": 13,
      "y": 9,
      "z": 0,
      "color": "#8a8a8a"
    },
    {
      "x": 13,
      "y": 9,
      "z": 15,
      "color": "#8a8a8a"
    },
    {
      "x": 13,
      "y": 10,
      "z": 0,
      "color": "#8a8a8a"
    },
    {
      "x": 13,
      "y": 10,
      "z": 15,
      "color": "#8a8a8a"
    },
    {
      "x": 13,
      "y": 11,
      "z": 0,
      "color": "#8a8a8a"
    },
    {
      "x": 13,
      "y": 11,
      "z": 15,
      "color": "#8a8a8a"
    },
    {
      "x": 13,
      "y": 12,
      "z": 0,
      "color": "#6a6a6a"
    },
    {
      "x": 13,
      "y": 12,
      "z": 15,
      "color": "#6a6a6a"
    },
    {
      "x": 13,
      "y": 13,
      "z": 0,
      "color": "#9a9a9a"
    },
    {
      "x": 13,
      "y": 13,
      "z": 15,
      "color": "#9a9a9a"
    },
    {
      "x": 13,
      "y": 14,
      "z": 0,
      "color": "#8a8a8a"
    },
    {
      "x": 13,
      "y": 14,
      "z": 15,
      "color": "#8a8a8a"
    },
    {
      "x": 13,
      "y": 15,
      "z": 0,
      "color": "#8a8a8a"
    },
    {
      "x": 13,
      "y": 15,
      "z": 15,
      "color": "#8a8a8a"
    },
    {
      "x": 14,
      "y": 0,
      "z": 0,
      "color": "#8a8a8a"
    },
    {
      "x": 14,
      "y": 0,
      "z": 15,
      "color": "#8a8a8a"
    },
    {
      "x": 14,
      "y": 1,
      "z": 0,
      "color": "#6a6a6a"
    },
    {
      "x": 14,
      "y": 1,
      "z": 15,
      "color": "#6a6a6a"
    },
    {
      "x": 14,
      "y": 2,
      "z": 0,
      "color": "#9a9a9a"
    },
    {
      "x": 14,
      "y": 2,
      "z": 15,
      "color": "#9a9a9a"
    },
    {
      "x": 14,
      "y": 3,
      "z": 0,
      "color": "#8a8a8a"
    },
    {
      "x": 14,
      "y": 3,
      "z": 15,
      "color": "#8a8a8a"
    },
    {
      "x": 14,
      "y": 4,
      "z": 0,
      "color": "#8a8a8a"
    },
    {
      "x": 14,
      "y": 4,
      "z": 15,
      "color": "#8a8a8a"
    },
    {
      "x": 14,
      "y": 5,
      "z": 0,
      "color": "#8a8a8a"
    },
    {
      "x": 14,
      "y": 5,
      "z": 15,
      "color": "#8a8a8a"
    },
    {
      "x": 14,
      "y": 6,
      "z": 0,
      "color": "#6a6a6a"
    },
    {
      "x": 14,
      "y": 6,
      "z": 15,
      "color": "#6a6a6a"
    },
    {
      "x": 14,
      "y": 7,
      "z": 0,
      "color": "#9a9a9a"
    },
    {
      "x": 14,
      "y": 7,
      "z": 15,
      "color": "#9a9a9a"
    },
    {
      "x": 14,
      "y": 8,
      "z": 0,
      "color": "#8a8a8a"
    },
    {
      "x": 14,
      "y": 8,
      "z": 15,
      "color": "#8a8a8a"
    },
    {
      "x": 14,
      "y": 9,
      "z": 0,
      "color": "#8a8a8a"
    },
    {
      "x": 14,
      "y": 9,
      "z": 15,
      "color": "#8a8a8a"
    },
    {
      "x": 14,
      "y": 10,
      "z": 0,
      "color": "#8a8a8a"
    },
    {
      "x": 14,
      "y": 10,
      "z": 15,
      "color": "#8a8a8a"
    },
    {
      "x": 14,
      "y": 11,
      "z": 0,
      "color": "#6a6a6a"
    },
    {
      "x": 14,
      "y": 11,
      "z": 15,
      "color": "#6a6a6a"
    },
    {
      "x": 14,
      "y": 12,
      "z": 0,
      "color": "#9a9a9a"
    },
    {
      "x": 14,
      "y": 12,
      "z": 15,
      "color": "#9a9a9a"
    },
    {
      "x": 14,
      "y": 13,
      "z": 0,
      "color": "#8a8a8a"
    },
    {
      "x": 14,
      "y": 13,
      "z": 15,
      "color": "#8a8a8a"
    },
    {
      "x": 14,
      "y": 14,
      "z": 0,
      "color": "#8a8a8a"
    },
    {
      "x": 14,
      "y": 14,
      "z": 15,
      "color": "#8a8a8a"
    },
    {
      "x": 14,
      "y": 15,
      "z": 0,
      "color": "#8a8a8a"
    },
    {
      "x": 14,
      "y": 15,
      "z": 15,
      "color": "#8a8a8a"
    },
    {
      "x": 15,
      "y": 0,
      "z": 0,
      "color": "#6a6a6a"
    },
    {
      "x": 15,
      "y": 0,
      "z": 1,
      "color": "#9a9a9a"
    },
    {
      "x": 15,
      "y": 0,
      "z": 2,
      "color": "#8a8a8a"
    },
    {
      "x": 15,
      "y": 0,
      "z": 3,
      "color": "#8a8a8a"
    },
    {
      "x": 15,
      "y": 0,
      "z": 4,
      "color": "#8a8a8a"
    },
    {
      "x": 15,
      "y": 0,
      "z": 5,
      "color": "#6a6a6a"
    },
    {
      "x": 15,
      "y": 0,
      "z": 6,
      "color": "#9a9a9a"
    },
    {
      "x": 15,
      "y": 0,
      "z": 7,
      "color": "#8a8a8a"
    },
    {
      "x": 15,
      "y": 0,
      "z": 8,
      "color": "#8a8a8a"
    },
    {
      "x": 15,
      "y": 0,
      "z": 9,
      "color": "#8a8a8a"
    },
    {
      "x": 15,
      "y": 0,
      "z": 10,
      "color": "#6a6a6a"
    },
    {
      "x": 15,
      "y": 0,
      "z": 11,
      "color": "#9a9a9a"
    },
    {
      "x": 15,
      "y": 0,
      "z": 12,
      "color": "#8a8a8a"
    },
    {
      "x": 15,
      "y": 0,
      "z": 13,
      "color": "#8a8a8a"
    },
    {
      "x": 15,
      "y": 0,
      "z": 14,
      "color": "#8a8a8a"
    },
    {
      "x": 15,
      "y": 0,
      "z": 15,
      "color": "#6a6a6a"
    },
    {
      "x": 15,
      "y": 1,
      "z": 0,
      "color": "#9a9a9a"
    },
    {
      "x": 15,
      "y": 1,
      "z": 1,
      "color": "#8a8a8a"
    },
    {
      "x": 15,
      "y": 1,
      "z": 2,
      "color": "#8a8a8a"
    },
    {
      "x": 15,
      "y": 1,
      "z": 3,
      "color": "#8a8a8a"
    },
    {
      "x": 15,
      "y": 1,
      "z": 4,
      "color": "#6a6a6a"
    },
    {
      "x": 15,
      "y": 1,
      "z": 5,
      "color": "#9a9a9a"
    },
    {
      "x": 15,
      "y": 1,
      "z": 6,
      "color": "#8a8a8a"
    },
    {
      "x": 15,
      "y": 1,
      "z": 7,
      "color": "#8a8a8a"
    },
    {
      "x": 15,
      "y": 1,
      "z": 8,
      "color": "#8a8a8a"
    },
    {
      "x": 15,
      "y": 1,
      "z": 9,
      "color": "#6a6a6a"
    },
    {
      "x": 15,
      "y": 1,
      "z": 10,
      "color": "#9a9a9a"
    },
    {
      "x": 15,
      "y": 1,
      "z": 11,
      "color": "#8a8a8a"
    },
    {
      "x": 15,
      "y": 1,
      "z": 12,
      "color": "#8a8a8a"
    },
    {
      "x": 15,
      "y": 1,
      "z": 13,
      "color": "#8a8a8a"
    },
    {
      "x": 15,
      "y": 1,
      "z": 14,
      "color": "#6a6a6a"
    },
    {
      "x": 15,
      "y": 1,
      "z": 15,
      "color": "#9a9a9a"
    },
    {
      "x": 15,
      "y": 2,
      "z": 0,
      "color": "#8a8a8a"
    },
    {
      "x": 15,
      "y": 2,
      "z": 1,
      "color": "#8a8a8a"
    },
    {
      "x": 15,
      "y": 2,
      "z": 2,
      "color": "#8a8a8a"
    },
    {
      "x": 15,
      "y": 2,
      "z": 3,
      "color": "#6a6a6a"
    },
    {
      "x": 15,
      "y": 2,
      "z": 4,
      "color": "#9a9a9a"
    },
    {
      "x": 15,
      "y": 2,
      "z": 5,
      "color": "#8a8a8a"
    },
    {
      "x": 15,
      "y": 2,
      "z": 6,
      "color": "#8a8a8a"
    },
    {
      "x": 15,
      "y": 2,
      "z": 7,
      "color": "#8a8a8a"
    },
    {
      "x": 15,
      "y": 2,
      "z": 8,
      "color": "#6a6a6a"
    },
    {
      "x": 15,
      "y": 2,
      "z": 9,
      "color": "#9a9a9a"
    },
    {
      "x": 15,
      "y": 2,
      "z": 10,
      "color": "#8a8a8a"
    },
    {
      "x": 15,
      "y": 2,
      "z": 11,
      "color": "#8a8a8a"
    },
    {
      "x": 15,
      "y": 2,
      "z": 12,
      "color": "#8a8a8a"
    },
    {
      "x": 15,
      "y": 2,
      "z": 13,
      "color": "#6a6a6a"
    },
    {
      "x": 15,
      "y": 2,
      "z": 14,
      "color": "#9a9a9a"
    },
    {
      "x": 15,
      "y": 2,
      "z": 15,
      "color": "#8a8a8a"
    },
    {
      "x": 15,
      "y": 3,
      "z": 0,
      "color": "#8a8a8a"
    },
    {
      "x": 15,
      "y": 3,
      "z": 1,
      "color": "#8a8a8a"
    },
    {
      "x": 15,
      "y": 3,
      "z": 2,
      "color": "#4a6a8a"
    },
    {
      "x": 15,
      "y": 3,
      "z": 3,
      "color": "#4a6a8a"
    },
    {
      "x": 15,
      "y": 3,
      "z": 4,
      "color": "#8a8a8a"
    },
    {
      "x": 15,
      "y": 3,
      "z": 5,
      "color": "#8a8a8a"
    },
    {
      "x": 15,
      "y": 3,
      "z": 6,
      "color": "#8a8a8a"
    },
    {
      "x": 15,
      "y": 3,
      "z": 7,
      "color": "#6a6a6a"
    },
    {
      "x": 15,
      "y": 3,
      "z": 8,
      "color": "#9a9a9a"
    },
    {
      "x": 15,
      "y": 3,
      "z": 9,
      "color": "#8a8a8a"
    },
    {
      "x": 15,
      "y": 3,
      "z": 10,
      "color": "#4a6a8a"
    },
    {
      "x": 15,
      "y": 3,
      "z": 11,
      "color": "#4a6a8a"
    },
    {
      "x": 15,
      "y": 3,
      "z": 12,
      "color": "#6a6a6a"
    },
    {
      "x": 15,
      "y": 3,
      "z": 13,
      "color": "#9a9a9a"
    },
    {
      "x": 15,
      "y": 3,
      "z": 14,
      "color": "#8a8a8a"
    },
    {
      "x": 15,
      "y": 3,
      "z": 15,
      "color": "#8a8a8a"
    },
    {
      "x": 15,
      "y": 4,
      "z": 0,
      "color": "#8a8a8a"
    },
    {
      "x": 15,
      "y": 4,
      "z": 1,
      "color": "#6a6a6a"
    },
    {
      "x": 15,
      "y": 4,
      "z": 2,
      "color": "#4a6a8a"
    },
    {
      "x": 15,
      "y": 4,
      "z": 3,
      "color": "#4a6a8a"
    },
    {
      "x": 15,
      "y": 4,
      "z": 4,
      "color": "#8a8a8a"
    },
    {
      "x": 15,
      "y": 4,
      "z": 5,
      "color": "#8a8a8a"
    },
    {
      "x": 15,
      "y": 4,
      "z": 6,
      "color": "#6a6a6a"
    },
    {
      "x": 15,
      "y": 4,
      "z": 7,
      "color": "#9a9a9a"
    },
    {
      "x": 15,
      "y": 4,
      "z": 8,
      "color": "#8a8a8a"
    },
    {
      "x": 15,
      "y": 4,
      "z": 9,
      "color": "#8a8a8a"
    },
    {
      "x": 15,
      "y": 4,
      "z": 10,
      "color": "#4a6a8a"
    },
    {
      "x": 15,
      "y": 4,
      "z": 11,
      "color": "#4a6a8a"
    },
    {
      "x": 15,
      "y": 4,
      "z": 12,
      "color": "#9a9a9a"
    },
    {
      "x": 15,
      "y": 4,
      "z": 13,
      "color": "#8a8a8a"
    },
    {
      "x": 15,
      "y": 4,
      "z": 14,
      "color": "#8a8a8a"
    },
    {
      "x": 15,
      "y": 4,
      "z": 15,
      "color": "#8a8a8a"
    },
    {
      "x": 15,
      "y": 5,
      "z": 0,
      "color": "#6a6a6a"
    },
    {
      "x": 15,
      "y": 5,
      "z": 1,
      "color": "#9a9a9a"
    },
    {
      "x": 15,
      "y": 5,
      "z": 2,
      "color": "#8a8a8a"
    },
    {
      "x": 15,
      "y": 5,
      "z": 3,
      "color": "#8a8a8a"
    },
    {
      "x": 15,
      "y": 5,
      "z": 4,
      "color": "#8a8a8a"
    },
    {
      "x": 15,
      "y": 5,
      "z": 5,
      "color": "#6a6a6a"
    },
    {
      "x": 15,
      "y": 5,
      "z": 6,
      "color": "#9a9a9a"
    },
    {
      "x": 15,
      "y": 5,
      "z": 7,
      "color": "#8a8a8a"
    },
    {
      "x": 15,
      "y": 5,
      "z": 8,
      "color": "#8a8a8a"
    },
    {
      "x": 15,
      "y": 5,
      "z": 9,
      "color": "#8a8a8a"
    },
    {
      "x": 15,
      "y": 5,
      "z": 10,
      "color": "#6a6a6a"
    },
    {
      "x": 15,
      "y": 5,
      "z": 11,
      "color": "#9a9a9a"
    },
    {
      "x": 15,
      "y": 5,
      "z": 12,
      "color": "#8a8a8a"
    },
    {
      "x": 15,
      "y": 5,
      "z": 13,
      "color": "#8a8a8a"
    },
    {
      "x": 15,
      "y": 5,
      "z": 14,
      "color": "#8a8a8a"
    },
    {
      "x": 15,
      "y": 5,
      "z": 15,
      "color": "#6a6a6a"
    },
    {
      "x": 15,
      "y": 6,
      "z": 0,
      "color": "#9a9a9a"
    },
    {
      "x": 15,
      "y": 6,
      "z": 1,
      "color": "#8a8a8a"
    },
    {
      "x": 15,
      "y": 6,
      "z": 2,
      "color": "#8a8a8a"
    },
    {
      "x": 15,
      "y": 6,
      "z": 3,
      "color": "#8a8a8a"
    },
    {
      "x": 15,
      "y": 6,
      "z": 4,
      "color": "#6a6a6a"
    },
    {
      "x": 15,
      "y": 6,
      "z": 5,
      "color": "#9a9a9a"
    },
    {
      "x": 15,
      "y": 6,
      "z": 6,
      "color": "#8a8a8a"
    },
    {
      "x": 15,
      "y": 6,
      "z": 7,
      "color": "#8a8a8a"
    },
    {
      "x": 15,
      "y": 6,
      "z": 8,
      "color": "#8a8a8a"
    },
    {
      "x": 15,
      "y": 6,
      "z": 9,
      "color": "#6a6a6a"
    },
    {
      "x": 15,
      "y": 6,
      "z": 10,
      "color": "#9a9a9a"
    },
    {
      "x": 15,
      "y": 6,
      "z": 11,
      "color": "#8a8a8a"
    },
    {
      "x": 15,
      "y": 6,
      "z": 12,
      "color": "#8a8a8a"
    },
    {
      "x": 15,
      "y": 6,
      "z": 13,
      "color": "#8a8a8a"
    },
    {
      "x": 15,
      "y": 6,
      "z": 14,
      "color": "#6a6a6a"
    },
    {
      "x": 15,
      "y": 6,
      "z": 15,
      "color": "#9a9a9a"
    },
    {
      "x": 15,
      "y": 7,
      "z": 0,
      "color": "#8a8a8a"
    },
    {
      "x": 15,
      "y": 7,
      "z": 1,
      "color": "#8a8a8a"
    },
    {
      "x": 15,
      "y": 7,
      "z": 2,
      "color": "#8a8a8a"
    },
    {
      "x": 15,
      "y": 7,
      "z": 3,
      "color": "#6a6a6a"
    },
    {
      "x": 15,
      "y": 7,
      "z": 4,
      "color": "#9a9a9a"
    },
    {
      "x": 15,
      "y": 7,
      "z": 5,
      "color": "#8a8a8a"
    },
    {
      "x": 15,
      "y": 7,
      "z": 6,
      "color": "#8a8a8a"
    },
    {
      "x": 15,
      "y": 7,
      "z": 7,
      "color": "#8a8a8a"
    },
    {
      "x": 15,
      "y": 7,
      "z": 8,
      "color": "#6a6a6a"
    },
    {
      "x": 15,
      "y": 7,
      "z": 9,
      "color": "#9a9a9a"
    },
    {
      "x": 15,
      "y": 7,
      "z": 10,
      "color": "#8a8a8a"
    },
    {
      "x": 15,
      "y": 7,
      "z": 11,
      "color": "#8a8a8a"
    },
    {
      "x": 15,
      "y": 7,
      "z": 12,
      "color": "#8a8a8a"
    },
    {
      "x": 15,
      "y": 7,
      "z": 13,
      "color": "#6a6a6a"
    },
    {
      "x": 15,
      "y": 7,
      "z": 14,
      "color": "#9a9a9a"
    },
    {
      "x": 15,
      "y": 7,
      "z": 15,
      "color": "#8a8a8a"
    },
    {
      "x": 15,
      "y": 8,
      "z": 0,
      "color": "#8a8a8a"
    },
    {
      "x": 15,
      "y": 8,
      "z": 1,
      "color": "#8a8a8a"
    },
    {
      "x": 15,
      "y": 8,
      "z": 2,
      "color": "#6a6a6a"
    },
    {
      "x": 15,
      "y": 8,
      "z": 3,
      "color": "#9a9a9a"
    },
    {
      "x": 15,
      "y": 8,
      "z": 4,
      "color": "#8a8a8a"
    },
    {
      "x": 15,
      "y": 8,
      "z": 5,
      "color": "#8a8a8a"
    },
    {
      "x": 15,
      "y": 8,
      "z": 6,
      "color": "#8a8a8a"
    },
    {
      "x": 15,
      "y": 8,
      "z": 7,
      "color": "#6a6a6a"
    },
    {
      "x": 15,
      "y": 8,
      "z": 8,
      "color": "#9a9a9a"
    },
    {
      "x": 15,
      "y": 8,
      "z": 9,
      "color": "#8a8a8a"
    },
    {
      "x": 15,
      "y": 8,
      "z": 10,
      "color": "#8a8a8a"
    },
    {
      "x": 15,
      "y": 8,
      "z": 11,
      "color": "#8a8a8a"
    },
    {
      "x": 15,
      "y": 8,
      "z": 12,
      "color": "#6a6a6a"
    },
    {
      "x": 15,
      "y": 8,
      "z": 13,
      "color": "#9a9a9a"
    },
    {
      "x": 15,
      "y": 8,
      "z": 14,
      "color": "#8a8a8a"
    },
    {
      "x": 15,
      "y": 8,
      "z": 15,
      "color": "#8a8a8a"
    },
    {
      "x": 15,
      "y": 9,
      "z": 0,
      "color": "#8a8a8a"
    },
    {
      "x": 15,
      "y": 9,
      "z": 1,
      "color": "#6a6a6a"
    },
    {
      "x": 15,
      "y": 9,
      "z": 2,
      "color": "#4a6a8a"
    },
    {
      "x": 15,
      "y": 9,
      "z": 3,
      "color": "#4a6a8a"
    },
    {
      "x": 15,
      "y": 9,
      "z": 4,
      "color": "#8a8a8a"
    },
    {
      "x": 15,
      "y": 9,
      "z": 5,
      "color": "#8a8a8a"
    },
    {
      "x": 15,
      "y": 9,
      "z": 6,
      "color": "#6a6a6a"
    },
    {
      "x": 15,
      "y": 9,
      "z": 7,
      "color": "#9a9a9a"
    },
    {
      "x": 15,
      "y": 9,
      "z": 8,
      "color": "#8a8a8a"
    },
    {
      "x": 15,
      "y": 9,
      "z": 9,
      "color": "#8a8a8a"
    },
    {
      "x": 15,
      "y": 9,
      "z": 10,
      "color": "#4a6a8a"
    },
    {
      "x": 15,
      "y": 9,
      "z": 11,
      "color": "#4a6a8a"
    },
    {
      "x": 15,
      "y": 9,
      "z": 12,
      "color": "#9a9a9a"
    },
    {
      "x": 15,
      "y": 9,
      "z": 13,
      "color": "#8a8a8a"
    },
    {
      "x": 15,
      "y": 9,
      "z": 14,
      "color": "#8a8a8a"
    },
    {
      "x": 15,
      "y": 9,
      "z": 15,
      "color": "#8a8a8a"
    },
    {
      "x": 15,
      "y": 10,
      "z": 0,
      "color": "#6a6a6a"
    },
    {
      "x": 15,
      "y": 10,
      "z": 1,
      "color": "#9a9a9a"
    },
    {
      "x": 15,
      "y": 10,
      "z": 2,
      "color": "#4a6a8a"
    },
    {
      "x": 15,
      "y": 10,
      "z": 3,
      "color": "#4a6a8a"
    },
    {
      "x": 15,
      "y": 10,
      "z": 4,
      "color": "#8a8a8a"
    },
    {
      "x": 15,
      "y": 10,
      "z": 5,
      "color": "#6a6a6a"
    },
    {
      "x": 15,
      "y": 10,
      "z": 6,
      "color": "#9a9a9a"
    },
    {
      "x": 15,
      "y": 10,
      "z": 7,
      "color": "#8a8a8a"
    },
    {
      "x": 15,
      "y": 10,
      "z": 8,
      "color": "#8a8a8a"
    },
    {
      "x": 15,
      "y": 10,
      "z": 9,
      "color": "#8a8a8a"
    },
    {
      "x": 15,
      "y": 10,
      "z": 10,
      "color": "#4a6a8a"
    },
    {
      "x": 15,
      "y": 10,
      "z": 11,
      "color": "#4a6a8a"
    },
    {
      "x": 15,
      "y": 10,
      "z": 12,
      "color": "#8a8a8a"
    },
    {
      "x": 15,
      "y": 10,
      "z": 13,
      "color": "#8a8a8a"
    },
    {
      "x": 15,
      "y": 10,
      "z": 14,
      "color": "#8a8a8a"
    },
    {
      "x": 15,
      "y": 10,
      "z": 15,
      "color": "#6a6a6a"
    },
    {
      "x": 15,
      "y": 11,
      "z": 0,
      "color": "#9a9a9a"
    },
    {
      "x": 15,
      "y": 11,
      "z": 1,
      "color": "#8a8a8a"
    },
    {
      "x": 15,
      "y": 11,
      "z": 2,
      "color": "#8a8a8a"
    },
    {
      "x": 15,
      "y": 11,
      "z": 3,
      "color": "#8a8a8a"
    },
    {
      "x": 15,
      "y": 11,
      "z": 4,
      "color": "#6a6a6a"
    },
    {
      "x": 15,
      "y": 11,
      "z": 5,
      "color": "#9a9a9a"
    },
    {
      "x": 15,
      "y": 11,
      "z": 6,
      "color": "#8a8a8a"
    },
    {
      "x": 15,
      "y": 11,
      "z": 7,
      "color": "#8a8a8a"
    },
    {
      "x": 15,
      "y": 11,
      "z": 8,
      "color": "#8a8a8a"
    },
    {
      "x": 15,
      "y": 11,
      "z": 9,
      "color": "#6a6a6a"
    },
    {
      "x": 15,
      "y": 11,
      "z": 10,
      "color": "#9a9a9a"
    },
    {
      "x": 15,
      "y": 11,
      "z": 11,
      "color": "#8a8a8a"
    },
    {
      "x": 15,
      "y": 11,
      "z": 12,
      "color": "#8a8a8a"
    },
    {
      "x": 15,
      "y": 11,
      "z": 13,
      "color": "#8a8a8a"
    },
    {
      "x": 15,
      "y": 11,
      "z": 14,
      "color": "#6a6a6a"
    },
    {
      "x": 15,
      "y": 11,
      "z": 15,
      "color": "#9a9a9a"
    },
    {
      "x": 15,
      "y": 12,
      "z": 0,
      "color": "#8a8a8a"
    },
    {
      "x": 15,
      "y": 12,
      "z": 1,
      "color": "#8a8a8a"
    },
    {
      "x": 15,
      "y": 12,
      "z": 2,
      "color": "#8a8a8a"
    },
    {
      "x": 15,
      "y": 12,
      "z": 3,
      "color": "#6a6a6a"
    },
    {
      "x": 15,
      "y": 12,
      "z": 4,
      "color": "#9a9a9a"
    },
    {
      "x": 15,
      "y": 12,
      "z": 5,
      "color": "#8a8a8a"
    },
    {
      "x": 15,
      "y": 12,
      "z": 6,
      "color": "#8a8a8a"
    },
    {
      "x": 15,
      "y": 12,
      "z": 7,
      "color": "#8a8a8a"
    },
    {
      "x": 15,
      "y": 12,
      "z": 8,
      "color": "#6a6a6a"
    },
    {
      "x": 15,
      "y": 12,
      "z": 9,
      "color": "#9a9a9a"
    },
    {
      "x": 15,
      "y": 12,
      "z": 10,
      "color": "#8a8a8a"
    },
    {
      "x": 15,
      "y": 12,
      "z": 11,
      "color": "#8a8a8a"
    },
    {
      "x": 15,
      "y": 12,
      "z": 12,
      "color": "#8a8a8a"
    },
    {
      "x": 15,
      "y": 12,
      "z": 13,
      "color": "#6a6a6a"
    },
    {
      "x": 15,
      "y": 12,
      "z": 14,
      "color": "#9a9a9a"
    },
    {
      "x": 15,
      "y": 12,
      "z": 15,
      "color": "#8a8a8a"
    },
    {
      "x": 15,
      "y": 13,
      "z": 0,
      "color": "#8a8a8a"
    },
    {
      "x": 15,
      "y": 13,
      "z": 1,
      "color": "#8a8a8a"
    },
    {
      "x": 15,
      "y": 13,
      "z": 2,
      "color": "#6a6a6a"
    },
    {
      "x": 15,
      "y": 13,
      "z": 3,
      "color": "#9a9a9a"
    },
    {
      "x": 15,
      "y": 13,
      "z": 4,
      "color": "#8a8a8a"
    },
    {
      "x": 15,
      "y": 13,
      "z": 5,
      "color": "#8a8a8a"
    },
    {
      "x": 15,
      "y": 13,
      "z": 6,
      "color": "#8a8a8a"
    },
    {
      "x": 15,
      "y": 13,
      "z": 7,
      "color": "#6a6a6a"
    },
    {
      "x": 15,
      "y": 13,
      "z": 8,
      "color": "#9a9a9a"
    },
    {
      "x": 15,
      "y": 13,
      "z": 9,
      "color": "#8a8a8a"
    },
    {
      "x": 15,
      "y": 13,
      "z": 10,
      "color": "#8a8a8a"
    },
    {
      "x": 15,
      "y": 13,
      "z": 11,
      "color": "#8a8a8a"
    },
    {
      "x": 15,
      "y": 13,
      "z": 12,
      "color": "#6a6a6a"
    },
    {
      "x": 15,
      "y": 13,
      "z": 13,
      "color": "#9a9a9a"
    },
    {
      "x": 15,
      "y": 13,
      "z": 14,
      "color": "#8a8a8a"
    },
    {
      "x": 15,
      "y": 13,
      "z": 15,
      "color": "#8a8a8a"
    },
    {
      "x": 15,
      "y": 14,
      "z": 0,
      "color": "#8a8a8a"
    },
    {
      "x": 15,
      "y": 14,
      "z": 1,
      "color": "#6a6a6a"
    },
    {
      "x": 15,
      "y": 14,
      "z": 2,
      "color": "#9a9a9a"
    },
    {
      "x": 15,
      "y": 14,
      "z": 3,
      "color": "#8a8a8a"
    },
    {
      "x": 15,
      "y": 14,
      "z": 4,
      "color": "#8a8a8a"
    },
    {
      "x": 15,
      "y": 14,
      "z": 5,
      "color": "#8a8a8a"
    },
    {
      "x": 15,
      "y": 14,
      "z": 6,
      "color": "#6a6a6a"
    },
    {
      "x": 15,
      "y": 14,
      "z": 7,
      "color": "#9a9a9a"
    },
    {
      "x": 15,
      "y": 14,
      "z": 8,
      "color": "#8a8a8a"
    },
    {
      "x": 15,
      "y": 14,
      "z": 9,
      "color": "#8a8a8a"
    },
    {
      "x": 15,
      "y": 14,
      "z": 10,
      "color": "#8a8a8a"
    },
    {
      "x": 15,
      "y": 14,
      "z": 11,
      "color": "#6a6a6a"
    },
    {
      "x": 15,
      "y": 14,
      "z": 12,
      "color": "#9a9a9a"
    },
    {
      "x": 15,
      "y": 14,
      "z": 13,
      "color": "#8a8a8a"
    },
    {
      "x": 15,
      "y": 14,
      "z": 14,
      "color": "#8a8a8a"
    },
    {
      "x": 15,
      "y": 14,
      "z": 15,
      "color": "#8a8a8a"
    },
    {
      "x": 15,
      "y": 15,
      "z": 0,
      "color": "#6a6a6a"
    },
    {
      "x": 15,
      "y": 15,
      "z": 1,
      "color": "#9a9a9a"
    },
    {
      "x": 15,
      "y": 15,
      "z": 2,
      "color": "#4a6a8a"
    },
    {
      "x": 15,
      "y": 15,
      "z": 3,
      "color": "#4a6a8a"
    },
    {
      "x": 15,
      "y": 15,
      "z": 4,
      "color": "#8a8a8a"
    },
    {
      "x": 15,
      "y": 15,
      "z": 5,
      "color": "#6a6a6a"
    },
    {
      "x": 15,
      "y": 15,
      "z": 6,
      "color": "#9a9a9a"
    },
    {
      "x": 15,
      "y": 15,
      "z": 7,
      "color": "#8a8a8a"
    },
    {
      "x": 15,
      "y": 15,
      "z": 8,
      "color": "#8a8a8a"
    },
    {
      "x": 15,
      "y": 15,
      "z": 9,
      "color": "#8a8a8a"
    },
    {
      "x": 15,
      "y": 15,
      "z": 10,
      "color": "#4a6a8a"
    },
    {
      "x": 15,
      "y": 15,
      "z": 11,
      "color": "#4a6a8a"
    },
    {
      "x": 15,
      "y": 15,
      "z": 12,
      "color": "#8a8a8a"
    },
    {
      "x": 15,
      "y": 15,
      "z": 13,
      "color": "#8a8a8a"
    },
    {
      "x": 15,
      "y": 15,
      "z": 14,
      "color": "#8a8a8a"
    },
    {
      "x": 15,
      "y": 15,
      "z": 15,
      "color": "#6a6a6a"
    },
    {
      "x": 0,
      "y": 15,
      "z": 0,
      "color": "#6a6a6a"
    },
    {
      "x": 0,
      "y": 15,
      "z": 1,
      "color": "#6a6a6a"
    },
    {
      "x": 0,
      "y": 15,
      "z": 2,
      "color": "#6a6a6a"
    },
    {
      "x": 0,
      "y": 15,
      "z": 3,
      "color": "#6a6a6a"
    },
    {
      "x": 0,
      "y": 15,
      "z": 4,
      "color": "#6a6a6a"
    },
    {
      "x": 0,
      "y": 15,
      "z": 5,
      "color": "#6a6a6a"
    },
    {
      "x": 0,
      "y": 15,
      "z": 6,
      "color": "#6a6a6a"
    },
    {
      "x": 0,
      "y": 15,
      "z": 7,
      "color": "#6a6a6a"
    },
    {
      "x": 0,
      "y": 15,
      "z": 8,
      "color": "#6a6a6a"
    },
    {
      "x": 0,
      "y": 15,
      "z": 9,
      "color": "#6a6a6a"
    },
    {
      "x": 0,
      "y": 15,
      "z": 10,
      "color": "#6a6a6a"
    },
    {
      "x": 0,
      "y": 15,
      "z": 11,
      "color": "#6a6a6a"
    },
    {
      "x": 0,
      "y": 15,
      "z": 12,
      "color": "#6a6a6a"
    },
    {
      "x": 0,
      "y": 15,
      "z": 13,
      "color": "#6a6a6a"
    },
    {
      "x": 0,
      "y": 15,
      "z": 14,
      "color": "#6a6a6a"
    },
    {
      "x": 0,
      "y": 15,
      "z": 15,
      "color": "#6a6a6a"
    },
    {
      "x": 1,
      "y": 15,
      "z": 0,
      "color": "#6a6a6a"
    },
    {
      "x": 1,
      "y": 15,
      "z": 15,
      "color": "#6a6a6a"
    },
    {
      "x": 2,
      "y": 15,
      "z": 0,
      "color": "#6a6a6a"
    },
    {
      "x": 2,
      "y": 15,
      "z": 15,
      "color": "#6a6a6a"
    },
    {
      "x": 3,
      "y": 15,
      "z": 0,
      "color": "#6a6a6a"
    },
    {
      "x": 3,
      "y": 15,
      "z": 15,
      "color": "#6a6a6a"
    },
    {
      "x": 4,
      "y": 15,
      "z": 0,
      "color": "#6a6a6a"
    },
    {
      "x": 4,
      "y": 15,
      "z": 15,
      "color": "#6a6a6a"
    },
    {
      "x": 5,
      "y": 15,
      "z": 0,
      "color": "#6a6a6a"
    },
    {
      "x": 5,
      "y": 15,
      "z": 15,
      "color": "#6a6a6a"
    },
    {
      "x": 6,
      "y": 15,
      "z": 0,
      "color": "#6a6a6a"
    },
    {
      "x": 6,
      "y": 15,
      "z": 15,
      "color": "#6a6a6a"
    },
    {
      "x": 7,
      "y": 15,
      "z": 0,
      "color": "#6a6a6a"
    },
    {
      "x": 7,
      "y": 15,
      "z": 15,
      "color": "#6a6a6a"
    },
    {
      "x": 8,
      "y": 15,
      "z": 0,
      "color": "#6a6a6a"
    },
    {
      "x": 8,
      "y": 15,
      "z": 15,
      "color": "#6a6a6a"
    },
    {
      "x": 9,
      "y": 15,
      "z": 0,
      "color": "#6a6a6a"
    },
    {
      "x": 9,
      "y": 15,
      "z": 15,
      "color": "#6a6a6a"
    },
    {
      "x": 10,
      "y": 15,
      "z": 0,
      "color": "#6a6a6a"
    },
    {
      "x": 10,
      "y": 15,
      "z": 15,
      "color": "#6a6a6a"
    },
    {
      "x": 11,
      "y": 15,
      "z": 0,
      "color": "#6a6a6a"
    },
    {
      "x": 11,
      "y": 15,
      "z": 15,
      "color": "#6a6a6a"
    },
    {
      "x": 12,
      "y": 15,
      "z": 0,
      "color": "#6a6a6a"
    },
    {
      "x": 12,
      "y": 15,
      "z": 15,
      "color": "#6a6a6a"
    },
    {
      "x": 13,
      "y": 15,
      "z": 0,
      "color": "#6a6a6a"
    },
    {
      "x": 13,
      "y": 15,
      "z": 15,
      "color": "#6a6a6a"
    },
    {
      "x": 14,
      "y": 15,
      "z": 0,
      "color": "#6a6a6a"
    },
    {
      "x": 14,
      "y": 15,
      "z": 15,
      "color": "#6a6a6a"
    },
    {
      "x": 15,
      "y": 15,
      "z": 0,
      "color": "#6a6a6a"
    },
    {
      "x": 15,
      "y": 15,
      "z": 1,
      "color": "#6a6a6a"
    },
    {
      "x": 15,
      "y": 15,
      "z": 2,
      "color": "#6a6a6a"
    },
    {
      "x": 15,
      "y": 15,
      "z": 3,
      "color": "#6a6a6a"
    },
    {
      "x": 15,
      "y": 15,
      "z": 4,
      "color": "#6a6a6a"
    },
    {
      "x": 15,
      "y": 15,
      "z": 5,
      "color": "#6a6a6a"
    },
    {
      "x": 15,
      "y": 15,
      "z": 6,
      "color": "#6a6a6a"
    },
    {
      "x": 15,
      "y": 15,
      "z": 7,
      "color": "#6a6a6a"
    },
    {
      "x": 15,
      "y": 15,
      "z": 8,
      "color": "#6a6a6a"
    },
    {
      "x": 15,
      "y": 15,
      "z": 9,
      "color": "#6a6a6a"
    },
    {
      "x": 15,
      "y": 15,
      "z": 10,
      "color": "#6a6a6a"
    },
    {
      "x": 15,
      "y": 15,
      "z": 11,
      "color": "#6a6a6a"
    },
    {
      "x": 15,
      "y": 15,
      "z": 12,
      "color": "#6a6a6a"
    },
    {
      "x": 15,
      "y": 15,
      "z": 13,
      "color": "#6a6a6a"
    },
    {
      "x": 15,
      "y": 15,
      "z": 14,
      "color": "#6a6a6a"
    },
    {
      "x": 15,
      "y": 15,
      "z": 15,
      "color": "#6a6a6a"
    }
  ]
}